Workbook
Name D.ACESS.SOBRE_TOT.PROD: #REF!
Name DESP.ACESS.: #REF!
Name ICMS_ST_DO_TOTAL_DOS_PRODUTOS: #REF!
Name PERCENT_ICMS_ST_DO_TOTAL_DOS_PRODUTOS: #REF!
Name QT.A: #REF!
Name QT.B: #REF!
Name QT.C: #REF!
Name QT.D: #REF!
Name QTD._A: #REF!
Name QTD._B: #REF!
Name QTD._C: #REF!
Name QTD.A: #REF!
Name QTD.B: #REF!
Name QTD.C: #REF!
Name QTD.D: #REF!
Name TOT_NF: #REF!
Name TOT_PROD: #REF!
Name VALOR_DO_ICMS_ST: #REF!
Name VALOR_TOTAL_DA_NOTA: #REF!
Name VALOR_TOTAL_DOS_PRODUTOS: #REF!
Name VLR.TOTAL_A: #REF!
Name VLR.TOTAL_B: #REF!
Name VLR.TOTAL_C: #REF!
Name VLR.TOTAL_D: #REF!
Name VR.TOT.A: #REF!
Name VR.TOT.B: #REF!
Name VR.TOT.C: #REF!

Sheet ORIENTAÇÕES E CONF.
A1: CONFERÊNCIAS (ELABORAÇÃO INICIADA EM 03/11/2025) | B1: SEM ALTERAÇÃO | C1: (NÃO É FÓRMULA) | D1: AS EXPRESSÕES
A2: SITUAÇÃO: : | B2: A PREENCHER | C2: (NÃO É FÓRMULA) | D2: "CONFERIDO"
B3: EM EXECUÇÃO | C3: (NÃO É FÓRMULA) | D3: E
A4: CONDOMÍNIO E FUNDO DE RESERVA COM VENCIMENTO EM: | B4: CONFERIR PREENCHTº | C4: (NÃO É FÓRMULA) | D4: "PENDENTE"
A5: 46113 | B5: JÁ CONFERIDO | C5: (NÃO É FÓRMULA) | D5: SÃO FÓRMULAS! | F5: INÍCIO | G5: TÉRMINO
A6: ITEM | B6: SITUAÇÃO | C6: OBS. 1 | D6: OBS. 2 | F6: 05/01,28/01
A7: TABELA "GÁS" DA PLANILHA "MEDIÇÕES E TABELAS" | B7: SEM ALTERAÇÃO | C7: FALTA ALTERAR FÓRMULA DA COLUNA "VALOR" DO GÁS DA TABELA 2 DA PLANILHA "MEDIÇÕES E TABELAS" | F7: 05/01,28/01
A8: TABELA "COPASA NFFS" DA PLANILHA "MEDIÇÕES E TABELAS" (MENSALMENTE: ELIMINAR DESTA TABELA A 1ª LINHA; COPIAR/COLAR A ÚLTIMA LINHA NA TABELA IDÊNTICA DA PLANILHA "MEDIÇÕES E COPASA HISTÓRICO") | B8: EM EXECUÇÃO | C8: VERIFICAR SE FOI RETIRADA (DA CONTA DA LEITURA DE 25/02/26, QUE VENCE EM 15/04/26) A MULTA POR ATRASO DE PAGAMENTO (PROTOCOLO 20260304870368, DE 04/03/26), REF. À CONTA DA LEITURA DE 29/12/25, QUE PAGUEI NO DIA 18/02/26: VENCEU NO DIA 15/02/26, UM DOMINGO, E OS DIAS 16 E 17 FORAM DEFINIDOS COMO FERIADOS BANCÁRIOS. PREVISÃO DE ATENDIMENTO: ATÉ 18/03/26.
A9: LEITURA DE ÁGUA E GÁS | B9: JÁ CONFERIDO
A10: TABELA 1 DA PLANILHA "MEDIÇÕES E TABELAS" (MENSALMENTE: ELIMINAR DA "TABELA 1" A 1ª LINHA DE ÁGUA E A 1ª DE GÁS; COPIAR/COLAR A ÚLTIMA LINHA DE CADA ITEM NA TABELA IDÊNTICA DA PLANILHA "MEDIÇÕES E COPASA HISTÓRICO". CONFERIR NA LINHA "A (-) B" DA LEITURA ATUAL SE HÁ CONSUMO ANORMAL DE ÁGUA E AVISAR AO CONDÔMINO SE HOUVER) | B10: JÁ CONFERIDO | C10: FALTA VERIFICAR SE HOUVE CONSUMO ANORMAL DE ÁGUA: APTºS 401 (IGUAL AO MÊS ANTERIOR), 501 E 602, JÁ AVISADOS +- EM 01/03/26
A11: TABELA 2 DA PLANILHA "MEDIÇÕES E TABELAS" (PROCEDIMENTOS: 1- SEMPRE ATUALIZAR OS DADOS DO CABEÇALHO DA TABELA; 2- SELECIONAR AS CORRESPONDENTES COLUNAS DA TABELA 2 E SUBSTITUIR O Nº DA LINHA ANTERIOR PELA LINHA ATUAL, COM DADOS DA TABELA 1) | B11: JÁ CONFERIDO
A12: TABELA "% DO CONSUMO TOTAL", À DIREITA DA TABELA 2 DA PLANILHA "MEDIÇÕES E TABELAS" (MENSALMENTE: ELIMINAR DESTA TABELA A 1ª COLUNA DATADA; COPIAR/COLAR A ÚLTIMA COLUNA NA TABELA IDÊNTICA DA PLANILHA "MEDIÇÕES E COPASA HISTÓRICO") | B12: JÁ CONFERIDO
A13: TABELA "RATEIOS DE COPASA E SÍNDICO", À DIREITA DA TABELA 2 DA PLANILHA "MEDIÇÕES E TABELAS" (MENSALMENTE: ELIMINAR DESTA TABELA A 1ª LINHA; COPIAR/COLAR A ÚLTIMA LINHA NA TABELA IDÊNTICA DA PLANILHA "MEDIÇÕES E COPASA HISTÓRICO") | B13: JÁ CONFERIDO | C13: FALTA OBTER O VALOR NA PLANILHA LANÇTºS DA FÓRMULA DA CÉLULA AT42
A14: TABELA 3 DA PLANILHA "MEDIÇÕES E TABELAS" COINCIDE COM IGUAL TABELA DA PLANILHA "PLAN P COND" (SEMPRE ATUALIZAR OS DADOS DO CABEÇALHO DA TABELA. ATUALIZAR TAMBÉM OS DADOS DE SALDO DA LINHA DO APTº 801) | B14: =IF('MEDIÇÕES E TABELAS'!G135,"CONFERIDO","PENDENTE") -> CONFERIDO | C14: EM EXECUÇÃO
A15: TABELA 3, DA PLANILHA "MEDIÇÕES E TABELAS": PREENCHER AS 5 COLUNAS À DIREITA DA 2ª COLUNA INTITULADA "TOTAL A PAGAR" | B15: EM EXECUÇÃO
A16: TABELA 3 DA PLANILHA "MEDIÇÕES E TABELAS", COLUNA "RATEIO" | B16: JÁ CONFERIDO
A17: TABELA ABAIXO DA TABELA 3, DA PLANILHA "MEDIÇÕES E TABELAS" (A SER COLADA EM TABELA IDÊNTICA EXISTENTE NA PLANILHA "VRS. DEVIDOS E OUTROS") | B17: JÁ CONFERIDO
A18: PLANILHA "LANÇTºS" COINCIDE COM OS LANÇAMENTOS DA PLANILHA "PLAN P COND" (BUSCAR DADOS DE DESPESAS NO ARQUIVO "Adm" E NOS DEMAIS ARQUIVOS DA PASTA "H\Outr\Condomínio Neápolis") | B18: =IF(LANÇTºS!AQ37,"CONFERIDO","PENDENTE") -> CONFERIDO | C18: EM EXECUÇÃO
A19: PLANILHA "LANÇTºS": ATUALIZAR AS FÓRMULAS DA LINHA "PAGAMENTO SERVIÇO DO SÍNDICO" | B19: JÁ CONFERIDO
A20: PLANILHA "LANÇTºS": ATUALIZAR AS FÓRMULAS DAS 2 LINHAS "CONTA DE ÁGUA DO CONDOMÍNIO" - DEPOIS DE PRONTA: COPIAR/COLAR A TABELA TODA ABAIXO DA EXISTENTE, E A SEGUIR COPIAR/COLAR ESPECIAL TEXTO A TABELA TODA EM CIMA DA QUE JÁ FOI COLADA (ASSIM OS VALORES SERÃO FIXADOS CONFORME OS EXISTENTES NA TABELA ORIGINAL, MAS SEM FÓRMULAS) - CONFERIR FÓRMULA "VERDADEIRO" | B20: EM EXECUÇÃO
A21: TABELA "VALORES DEVIDOS POR UNIDADE" DA PLANILHA "VRS. DEVIDOS E OUTROS": COLAR/TRANSPOR PARA LÁ OS DADOS DA TABELA ABAIXO DA TABELA 3 DA PLANILHA "MEDIÇÕES E TABELAS"
A22: TABELA "VALORES DEVIDOS POR UNIDADE" DA PLANILHA "VRS. DEVIDOS E OUTROS", 1ª LINHA DE CONFERÊNCIA | B22: =IF('VRS. DEVIDOS E OUTROS'!R87,"CONFERIDO","PENDENTE") -> CONFERIDO | C22: FALTA ANALISAR CONSUMO ANORMAL DE ÁGUA (APTº 401: EXCESSO) E TOTAL A PAGAR
A23: TABELA "VALORES DEVIDOS POR UNIDADE" DA PLANILHA "VRS. DEVIDOS E OUTROS", 2ª LINHA DE CONFERÊNCIA - DEPOIS DE PRONTA: 1) COPIAR/COLAR A TABELA TODA À DIREITA DA EXISTENTE, E A SEGUIR COPIAR/COLAR ESPECIAL TEXTO A TABELA TODA EM CIMA DA QUE JÁ FOI COLADA (ASSIM OS VALORES SERÃO FIXADOS CONFORME OS EXISTENTES NA TABELA ORIGINAL, MAS SEM FÓRMULAS) - CONFERIR FÓRMULA "VERDADEIRO"; 2) ANALISAR SE HÁ CONSUMO ANORMAL DE ÁGUA E AVISAR AO CONDÔMINO SE HOUVER | B23: =IF('VRS. DEVIDOS E OUTROS'!R88,"CONFERIDO","PENDENTE") -> CONFERIDO | C23: EM EXECUÇÃO
A24: TABELA "RATEIO MENSAL" DA PLANILHA "VRS. DEVIDOS E OUTROS" COINCIDE COM O QUE CONSTA NA PLANILHA "PLAN P COND" (ATUALIZAR VALORES DA COLUNA "RATEIO" DA TABELA 3 DA PLANILHA "MEDIÇÕES E TABELAS") - DEPOIS DE PRONTA: COPIAR/COLAR A TABELA TODA À DIREITA DA EXISTENTE, E A SEGUIR COPIAR/COLAR ESPECIAL TEXTO A TABELA TODA EM CIMA DA QUE JÁ FOI COLADA (ASSIM OS VALORES SERÃO FIXADOS CONFORME OS EXISTENTES NA TABELA ORIGINAL, MAS SEM FÓRMULAS) - CONFERIR FÓRMULA "VERDADEIRO" | B24: =IF('VRS. DEVIDOS E OUTROS'!F103,"CONFERIDO","PENDENTE") -> CONFERIDO | C24: EM EXECUÇÃO
A25: TABELA "APTº 801" DA PLANILHA "VRS. DEVIDOS E OUTROS" - DEPOIS DE PRONTA: COPIAR/COLAR A TABELA TODA À DIREITA DA EXISTENTE, E A SEGUIR COPIAR/COLAR ESPECIAL TEXTO A TABELA TODA EM CIMA DA QUE JÁ FOI COLADA (ASSIM OS VALORES SERÃO FIXADOS CONFORME OS EXISTENTES NA TABELA ORIGINAL, MAS SEM FÓRMULAS) - CONFERIR FÓRMULA "VERDADEIRO" | B25: =IF('VRS. DEVIDOS E OUTROS'!H109,"CONFERIDO","PENDENTE") -> CONFERIDO | C25: EM EXECUÇÃO
A26: TABELA "APTº 201" (E TEXTO CORRESPONDENTE) DA PLANILHA "VRS. DEVIDOS E OUTROS" - DEPOIS DE PRONTA: COPIAR/COLAR A TABELA TODA À DIREITA DA EXISTENTE, E A SEGUIR COPIAR/COLAR ESPECIAL TEXTO A TABELA TODA EM CIMA DA QUE JÁ FOI COLADA (ASSIM OS VALORES SERÃO FIXADOS CONFORME OS EXISTENTES NA TABELA ORIGINAL, MAS SEM FÓRMULAS)
A27: TABELA "APTº 601" (E TEXTO CORRESPONDENTE) DA PLANILHA "VRS. DEVIDOS E OUTROS" - DEPOIS DE PRONTA: COPIAR/COLAR A TABELA TODA À DIREITA DA EXISTENTE, E A SEGUIR COPIAR/COLAR ESPECIAL TEXTO A TABELA TODA EM CIMA DA QUE JÁ FOI COLADA (ASSIM OS VALORES SERÃO FIXADOS CONFORME OS EXISTENTES NA TABELA ORIGINAL, MAS SEM FÓRMULAS)
A28: TABELA "FUNDO DE RESERVA" DA PLANILHA "VRS. DEVIDOS E OUTROS": SALDO ATUAL COINCIDE COM O QUE ESTÁ NA PLANILHA "PLAN P COND" (ÚLTIMA COLUNA: ADICIONAR VALOR DA COLUNA "SALDO ATUAL CONF. BANCO (B)"DO ARQUIVO "EXTRATO". A SEGUIR: ATUALIZAR VALOR DA COLUNA "FUNDO DE RESERVA" DO ARQUIVO "EXTRATO") - DEPOIS DE PRONTA: COPIAR/COLAR A TABELA TODA À DIREITA DA EXISTENTE, E A SEGUIR COPIAR/COLAR ESPECIAL TEXTO A TABELA TODA EM CIMA DA QUE JÁ FOI COLADA (ASSIM OS VALORES SERÃO FIXADOS CONFORME OS EXISTENTES NA TABELA ORIGINAL, MAS SEM FÓRMULAS) - CONFERIR FÓRMULA "VERDADEIRO" | B28: =IF('VRS. DEVIDOS E OUTROS'!U172,"CONFERIDO","PENDENTE") -> CONFERIDO | C28: EM EXECUÇÃO
A29: PLANILHA "DADOS DO PAGTº" (PREENCHER COM DADOS DA TABELA 3 DA PLANILHA "MEDIÇÕES E TABELAS", SOMENTE APÓS TEREM SIDO ENVIADOS TODOS OS RECIBOS AOS CONDÔMINOS - BLOQUEAR CÉLULAS APÓS CADA PREENCHIMENTO)
A30: PLANILHA P COND (EXCEL E PDF, VERIFICAR DIVERSAS FÓRMULAS NELA) E CÓPIA DELA NO ARQUIVO "Planilha p condôm 202302 em diante" SEM FÓRMULAS
A31: PLANILHA P COND (EXCEL E PDF), APTº 201
A32: PLANILHA P COND (EXCEL E PDF), APTº 601
A33: RECIBOS (ARQ. "Recibos 202511 em diante", NA PASTA "H\Outr\Condomínio Neápolis\Condôminos recibos", EXCEL E PDF - PREENCHTº AUTOMÁTICO POR FÓRMULAS (CONFERIR), EXCETO ALGUMAS PARTES DO RECIBO DO APTº 801, A ATUALIZAR
A34: PASTA "Banco Inter e outros": BAIXAR E SALVAR EM PDF NO MÊS SEGUINTE O EXTRATO DA CONTA CORRENTE DO MÊS ANTERIOR (A EXEMPLO DO ARQUIVO "Extrato 202509", DE 13/10/2025) | B34: A PREENCHER
A35: PASTA "Banco Inter e outros": BAIXAR E SALVAR EM PDF NO MÊS SEGUINTE O EXTRATO DA CONTA CORRENTE DO PERÍODO DE 01/2025 ATÉ O MÊS ANTERIOR, SUBSTITUINDO O ARQUIVO JÁ EXISTENTE (QUE EM 13/10/2025 ERA "Extrato 202501-202509") | B35: A PREENCHER
A36: PASTA "Banco Inter e outros": BAIXAR E SALVAR EM PDF NO MÊS SEGUINTE O EXTRATO DA "POSIÇÃO DE RENDA FIXA" DO ÚLTIMO DIA DO MÊS ANTERIOR, (A EXEMPLO DO ARQUIVO "extrato-posicao-renda-fixa 20250930", DE 13/10/2025) | B36: A PREENCHER
A37: ARQ. "Extrato", NA PASTA "Banco Inter e outros": PARA O ÚLTIMO DIA DE CADA MÊS, COPIAR/COLAR LINHA DO ÚLTIMO DIA DO MÊS ANTERIOR, ATUALIZANDO OS VALORES DAS COLUNAS "SALDO ATUAL CONF. BANCO (B)" (OBTIDO VIA ARQUIVO MAIS RECENTE DO "EXTRATO DA POSIÇÃO DE RENDA FIXA") E "FUNDO DE RESERVA" (OBTIDO NA PLANILHA "VRS. DEVIDOS E OUTROS" DO ARQUIVO "PLANILHAS MENSAIS 202508 EM DIANTE RASCUNHO EM USO", TABELA "FUNDO DE RESERVA") | B37: A PREENCHER
A38: ARQ. "Extrato", NA PASTA "Banco Inter e outros": ATUALIZÁ-LO DIARIAMENTE COM ENTRADAS E SAÍDAS , CONFERIR SEMPRE COM O EXTRATO DO APLICATIVO DO BANCO INTER | B38: EM EXECUÇÃO
A41: ORIENTAÇÕES (INICIADAS EM 13/08/2025, 4ª F.; ÚLTIMA ALTERAÇÃO: 06/11/2025, 5ª F.):
A43: EM TODAS AS PLANILHAS: AO ACRESCENTAR LINHA OU COLUNA, USAR "COPIAR" LINHA OU COLUNA / "INSERIR" CÉLULAS COPIADAS, PARA QUE NÃO SEJA ALTERADO O RESULTADO DAS DIVERSAS FÓRMULAS JÁ EXISTENTES.
...

Sheet MEDIÇÕES E COPASA HISTÓRICO
A1: TABELA 1 | AJ1: RATEIOS DE COPASA E SÍNDICO | AP1: COPASA NFFS | BA1: XXXXX | BB1: TARIFAS DA LEITURA DE 22/07/2025 (A QUE ESTAVA INCORRETA ATÉ 27/08/25) | BK1: TARIFAS DA LEITURA DE 22/08/2025 | BS1: XXXXX | BU1: GÁS (1KG COMPRADO É IGUAL A 2,5M3 CONSUMIDOS)
A2: LEITURA DOS MEDIDORES DE ÁGUA E GÁS (DIA 28 DE CADA MÊS) | AJ2: MÊS DO LANÇTº | AK2: COPASA DO COND. A RATEAR (R$) | AL2: COPASA DO COND. A RATEAR - SÓ FÓRMULA | AM2: PARTE DO SÍNDICO A RATEAR (COPASA, GÁS E DESPESAS, EM R$) | AN2: PARTE DO SÍNDICO A RATEAR - SÓ FÓRMULA | AP2: DATAS E CONSUMO | AU2: PARTE REF. À ÁGUA (R$) | AX2: PARTE REF. AO ESGOTO (R$) | BA2: COLUNAS OCULTAS (TABELAS COM SIMULAÇÃO DAS TARIFAS DAS LEITURAS DE 22/07 E 22/08/2025 ANTES DAS CORREÇÕES QUE A COPASA FEZ) | BB2: FX. CONSUMO M3 | BC2: CONSUMO DA FX. EM M3 | BD2: VOLUME TOTAL | BE2: R$/M3 DE ÁGUA | BF2: VR. DA ÁGUA | BG2: R$/M3 DE ESGOTO | BH2: VR. DO ESGOTO | BI2: SUBTOTAL | BK2: FX. CONSUMO M3 | BL2: CONSUMO DA FX. EM M3 | BM2: VOLUME TOTAL | BN2: R$/M3 DE ÁGUA | BO2: VR. DA ÁGUA | BP2: R$/M3 DE ESGOTO | BQ2: VR. DO ESGOTO | BR2: SUBTOTAL | BS2: COLUNAS OCULTAS (TABELAS COM SIMULAÇÃO DAS TARIFAS DAS LEITURAS DE 22/07 E 22/08/2025 ANTES DAS CORREÇÕES QUE A COPASA FEZ) | BU2: DATA ABASTECTº | BV2: QUANT. (KG) | BW2: PREÇO/KG (= NF) | BX2: TOTAL (R$) | BY2: PREÇO/KG ARREDOND. | BZ2: EQUIV. KG PARA M3 | CA2: CUSTO POR M3 (R$)
A3: DATA | B3: ITEM | C3: 201 | D3: 201 GÁS PISC. | E3: 202 | F3: 301 | G3: 302 | H3: 401 | I3: 402 | J3: 501 | K3: 502 | L3: 601 | M3: 602 | N3: 701 | O3: 702 | P3: 801 | Q3: 802 | R3: TOTAL | U3: % DO CONSUMO TOTAL, PARA CÁLCULO DO VALOR DO ESGOTO A SER | V3: UNIDADE / DATA DA LEITURA | W3: 45866 | X3: 45897 | Y3: 45928 | Z3: 45958 | AA3: 45988 | AB3: 46019 | AC3: 46050 | AD3: 46081 | AE3: 46109 | AP3: LEITURA | AQ3: VENCTº | AR3: QUITAÇÃO | AS3: CONSUMO TOTAL (M3) | AT3: TOTAL DA CONTA (R$) | AU3: ABASTECTº | AV3: USO DE REC. HÍDR. | AW3: PREÇO/M3 ARREDOND. | AX3: ESG. DINÂM. COLETA E TRATº | AY3: USO DE REC. HÍDR. | AZ3: OBS. | BB3: FIXA | BF3: 316.4 | BH3: 233.94 | BI3: =BF3+BH3 -> 550.34 | BK3: FIXA | BO3: 316.4 | BQ3: 233.94 | BR3: =BO3+BQ3 -> 550.34 | BU3: 2022 | BW3: 14.276 | BY3: 14.27 | BZ3: 2.5 | CA3: =BY3*BZ3 -> 35.675
A4: 44893 | B4: ÁGUA | C4: 2234.305 | D4: 0 | E4: 5533.646 | F4: 3691.878 | G4: 1620.994 | H4: 1650.543 | I4: 3784.605 | J4: 2565.364 | K4: 2088.147 | L4: 1940.531 | M4: 1841.097 | N4: 2711.44 | O4: 841.528 | P4: 5163.824 | Q4: 3048.163 | R4: =SUM(C4:Q4)-D4 -> 38716.065 | U4: COBRADO POR | V4: CONDOM. | W4: 0 | X4: 0.025 | Y4: 0.131 | Z4: 0.204 | AA4: 0.147 | AB4: 0 | AC4: 0 | AD4: 0 | AE4: 0.08 | AJ4: XXX | AK4: XXX | AL4: XXX | AM4: XXX | AN4: XXX | AP4: 44915 | AQ4: 44972 | AR4: 44937 | AS4: 225 | AT4: =AU4+AV4+AX4+AY4 -> 2077.63 | AU4: 1190.9 | AV4: 4.75 | AW4: =ROUNDUP((AU4+AV4)/AS4,2) -> 5.32 | AX4: 881.49 | AY4: 0.49 | BB4: 0 A 5 | BC4: 1.42857 | BD4: 20 | BE4: 2.34 | BF4: =ROUND(BD4*BE4,2) -> 46.8 | BG4: 1.73 | BH4: =BD4*BG4 -> 34.6 | BI4: =BF4+BH4 -> 81.4 | BK4: 0 A 5 | BL4: 5 | BM4: 70 | BN4: 2.34 | BO4: =ROUND(BM4*BN4,2) -> 163.8 | BP4: 1.73 | BQ4: =BM4*BP4 -> 121.1 | BR4: =BO4+BQ4 -> 284.9 | BU4: 44930 | BV4: =90.43+80.67 -> 171.1 | BW4: 13.315824 | BX4: =ROUND(BV4*BW4,2) -> 2278.34 | BY4: =ROUND(BW4,2) -> 13.32 | BZ4: 2.5 | CA4: =BY4*BZ4 -> 33.3
A5: 44923 | B5: ÁGUA | C5: 2251.956 | D5: 0 | E5: 5574.727 | F5: 3711.687 | G5: 1629.279 | H5: 1664.855 | I5: 3803.942 | J5: 2576.638 | K5: 2100.981 | L5: 1946.449 | M5: 1851.446 | N5: 2718.365 | O5: 845.468 | P5: 5175.426 | Q5: 3067.475 | R5: =SUM(C5:Q5) -> 38918.694 | U5: AP (COLAR AQUI | V5: 201 | W5: 0.051 | X5: 0.074 | Y5: 0.069 | Z5: 0.068 | AA5: 0.072 | AB5: 0.082 | AC5: 0.076 | AD5: 0.084 | AE5: 0.096 | AJ5: XXX | AK5: XXX | AL5: XXX | AM5: XXX | AN5: XXX | AP5: 44944 | AQ5: 45000 | AR5: 45000 | AS5: 226 | AT5: =AU5+AV5+AX5+AY5 -> 2295.67 | AU5: 1316.08 | AV5: 5.19 | AW5: =ROUND((AU5+AV5)/AS5,2) -> 5.85 | AX5: 973.87 | AY5: 0.53 | BB5: 5 A 10 | BK5: 5 A 10 | BL5: 5 | BM5: 70 | BN5: 4.987 | BO5: =ROUND(BM5*BN5,2) -> 349.09 | BP5: 3.69 | BQ5: =BM5*BP5 -> 258.3 | BR5: =BO5+BQ5 -> 607.39 | BU5: 45098 | BV5: 300.73 | BW5: 12.741595 | BX5: =ROUND(BV5*BW5,2) -> 3831.78 | BY5: =ROUND(BW5,2) -> 12.74 | BZ5: 2.5 | CA5: =BY5*BZ5 -> 31.85
A6: 44954 | B6: ÁGUA | C6: 2272.897 | D6: 0 | E6: 5608.529 | F6: 3732.161 | G6: 1640.201 | H6: 1685.537 | I6: 3827.285 | J6: 2587.655 | K6: 2114.097 | L6: 1951.375 | M6: 1855.796 | N6: 2727.694 | O6: 850.335 | P6: 5182.372 | Q6: 3087.528 | R6: =SUM(C6:Q6) -> 39123.462 | U6: O TEXTO DA COLUNA DA TABELA 2) | V6: 201 (ESPAÇO "201 GÁS PISC." DA TABELA DE LEITURAS, ZERADO) | W6: 0 | X6: 0 | Y6: 0 | Z6: 0 | AA6: 0 | AB6: 0 | AC6: 0 | AD6: 0 | AE6: 0 | AJ6: XXX | AK6: XXX | AL6: XXX | AM6: XXX | AN6: XXX | AP6: 44972 | AQ6: 45033 | AR6: 45033 | AS6: 218 | AT6: 2287.06 | AU6: 1311.45 | AV6: 4.82 | AW6: =ROUND((AU6+AV6)/AS6,2) -> 6.04 | AX6: 970.3 | AY6: 0.49 | BB6: 10 A 15 | BK6: 10 A 15 | BL6: 5 | BM6: 70 | BN6: 7.727 | BO6: =ROUND(BM6*BN6,2) -> 540.89 | BP6: 5.718 | BQ6: =BM6*BP6 -> 400.26 | BR6: =BO6+BQ6 -> 941.15 | BU6: 45296 | BV6: 280.22 | BW6: 12,809293 | BX6: =ROUND(BV6*BW6,2) -> 3589.42 | BY6: =ROUND(BW6,2) -> 12.81 | BZ6: 2.5 | CA6: =BY6*BZ6 -> 32.025
A7: 44985 | B7: ÁGUA | C7: 2291.597 | D7: 0 | E7: 5642.302 | F7: 3753.569 | G7: 1649.999 | H7: 1703.015 | I7: 3846.37 | J7: 2599.048 | K7: 2127.744 | L7: 1956.14 | M7: 1862.272 | N7: 2739.303 | O7: 855.383 | P7: 5194.27 | Q7: 3109.158 | R7: =SUM(C7:Q7) -> 39330.17 | V7: 202 | W7: 0.105 | X7: 0.081 | Y7: 0.093 | Z7: 0.035 | AA7: 0.078 | AB7: 0.101 | AC7: 0.11 | AD7: 0.097 | AE7: 0.073 | AJ7: XXX | AK7: XXX | AL7: XXX | AM7: XXX | AN7: XXX | AP7: 45005 | AQ7: 45061 | AR7: 45061 | AS7: 271 | AT7: 3164.51 | AU7: 1815.59 | AV7: 5.04 | AW7: =ROUND((AU7+AV7)/AS7,2) -> 6.72 | AX7: 1343.37 | AY7: 0.51 | BB7: 15 A 20 | BK7: 15 A 20 | BL7: 5 | BM7: 70 | BN7: 10.549 | BO7: =ROUND(BM7*BN7,2) -> 738.43 | BP7: 7.806 | BQ7: =BM7*BP7 -> 546.42 | BR7: =BO7+BQ7 -> 1284.85 | BU7: 45477 | BV7: 271.38 | BW7: 13.550888 | BX7: =ROUND(BV7*BW7,2) -> 3677.44 | BY7: =ROUND(BW7,2) -> 13.55 | BZ7: 2.5 | CA7: =BY7*BZ7 -> 33.875
A8: 45013 | B8: ÁGUA | C8: 2309.167 | D8: 0 | E8: 5681.365 | F8: 3770.995 | G8: 1659.162 | H8: 1713.004 | I8: 3861.947 | J8: 2608.132 | K8: 2139.578 | L8: 1959.986 | M8: 1866.638 | N8: 2746.466 | O8: 860.005 | P8: 5207.21 | Q8: 3127.691 | R8: =SUM(C8:Q8) -> 39511.346 | V8: 301 | W8: 0.066 | X8: 0.076 | Y8: 0.072 | Z8: 0.063 | AA8: 0.068 | AB8: 0.086 | AC8: 0.093 | AD8: 0.086 | AE8: 0.086 | AJ8: XXX | AK8: XXX | AL8: XXX | AM8: XXX | AN8: XXX | AP8: 45034 | AQ8: 45092 | AR8: 45092 | AS8: 219 | AT8: 2304.01 | AU8: 1320.97 | AV8: 5.17 | AW8: =ROUND((AU8+AV8)/AS8,2) -> 6.06 | AX8: 977.34 | AY8: 0.53 | BB8: 20 A 40 | BK8: 20 A 40 | BL8: 20 | BM8: 280 | BN8: 13.418 | BO8: =ROUND(BM8*BN8,2) -> 3757.04 | BP8: 9.929 | BQ8: =BM8*BP8 -> 2780.12 | BR8: =BO8+BQ8 -> 6537.16 | BU8: 45645 | BV8: 300.56 | BW8: 13.889373 | BX8: =ROUND(BV8*BW8,2) -> 4174.59 | BY8: =ROUND(BW8,2) -> 13.89 | BZ8: 2.5 | CA8: =BY8*BZ8 -> 34.725
A9: 45044 | B9: ÁGUA | C9: 2323.159 | D9: 0 | E9: 5724.987 | F9: 3788.481 | G9: 1673.075 | H9: 1726.402 | I9: 3879.6 | J9: 2619.173 | K9: 2149.099 | L9: 1967.14 | M9: 1873.535 | N9: 2756.556 | O9: 864.363 | P9: 5215.245 | Q9: 3149.161 | R9: =SUM(C9:Q9) -> 39709.976 | V9: 302 | W9: 0.096 | X9: 0.1 | Y9: 0.11 | Z9: 0.114 | AA9: 0.115 | AB9: 0.109 | AC9: 0.09 | AD9: 0.07 | AE9: 0.087 | AJ9: XXX | AK9: XXX | AL9: XXX | AM9: XXX | AN9: XXX | AP9: 45064 | AQ9: 45124 | AR9: 45124 | AS9: 238 | AT9: 2618.81 | AU9: 1501.7 | AV9: 5.47 | AW9: =ROUND((AU9+AV9)/AS9,2) -> 6.33 | AX9: 1111.08 | AY9: 0.56 | BB9: 40 A 60 | BK9: 40 A 60 | BL9: 5.42857 | BM9: 76 | BN9: 16.371 | BO9: =ROUND(BM9*BN9,2) -> 1244.2 | BP9: 12.112 | BQ9: =BM9*BP9 -> 920.512 | BR9: =BO9+BQ9 -> 2164.712 | BU9: 45815 | BV9: 283.91 | BW9: 15.065302 | BX9: =ROUND(BV9*BW9,2) -> 4277.19 | BY9: =ROUND(BW9,2) -> 15.07 | BZ9: 2.5 | CA9: =BY9*BZ9 -> 37.675
A10: 45074 | B10: ÁGUA | C10: 2343.659 | D10: 0 | E10: 5772.038 | F10: 3804.161 | G10: 1681.868 | H10: 1744.873 | I10: 3895.201 | J10: 2632.161 | K10: 2161.866 | L10: 1973.59 | M10: 1881.343 | N10: 2765.982 | O10: 868.777 | P10: 5221.618 | Q10: 3160.195 | R10: =SUM(C10:Q10) -> 39907.332 | V10: 401 | W10: 0.095 | X10: 0.101 | Y10: 0.113 | Z10: 0.117 | AA10: 0.127 | AB10: 0.127 | AC10: 0.141 | AD10: 0.136 | AE10: 0.112 | AJ10: XXX | AK10: XXX | AL10: XXX | AM10: XXX | AN10: XXX | AP10: 45096 | AQ10: 45153 | AR10: 45153 | AS10: 263 | AT10: 3031.13 | AU10: 1739.5 | AV10: 4.11 | AW10: =ROUND((AU10+AV10)/AS10,2) -> 6.63 | AX10: 1287.06 | AY10: 0.46 | BB10: SOMA | BC10: =SUM(BC4:BC8) -> 1.42857 | BD10: =SUM(BD4:BD8) -> 20 | BF10: =SUM(BF3:BF8) -> 363.2 | BH10: =SUM(BH3:BH8) -> 268.54 | BI10: =SUM(BI3:BI8) -> 631.74 | BK10: SOMA | BL10: =SUM(BL4:BL9) -> 45.42857 | BM10: =SUM(BM4:BM9) -> 636 | BO10: =SUM(BO3:BO9) -> 7109.85 | BQ10: =SUM(BQ3:BQ9) -> 5260.652 | BR10: =SUM(BR3:BR9) -> 12370.502 | BU10: 46025 | BV10: 320 | BW10: 15.145313 | BX10: =ROUND(BV10*BW10,2) -> 4846.5 | BY10: =ROUND(BW10,2) -> 15.15 | BZ10: 2.5 | CA10: =BY10*BZ10 -> 37.875
A11: 45105 | B11: ÁGUA | C11: 2361.768 | D11: 0 | E11: 5827.643 | F11: 3822.973 | G11: 1695.446 | H11: 1763.177 | I11: 3911.762 | J11: 2644.027 | K11: 2174.502 | L11: 1981.599 | M11: 1899.927 | N11: 2775.917 | O11: 873.956 | P11: 5229.375 | Q11: 3177.429 | R11: =SUM(C11:Q11) -> 40139.501 | V11: 402 | W11: 0.196 | X11: 0.201 | Y11: 0.076 | Z11: 0.074 | AA11: 0.078 | AB11: 0.073 | AC11: 0.086 | AD11: 0.094 | AE11: 0.104 | AJ11: XXX | AK11: XXX | AL11: XXX | AM11: XXX | AN11: XXX | AP11: 45126 | AQ11: 45185 | AR11: 45185 | AS11: 274 | AT11: 3213.33 | AU11: 1844.13 | AV11: 4.23 | AW11: =ROUND((AU11+AV11)/AS11,2) -> 6.75 | AX11: 1364.49 | AY11: 0.48 | BB11: USO REC. HÍDR. ÁGUA | BI11: 15.61 | BK11: USO REC. HÍDR. ÁGUA | BR11: 15.28
A12: 45138 | B12: ÁGUA | C12: 2376.043 | D12: 0 | E12: 5881.028 | F12: 3839.238 | G12: 1709.97 | H12: 1780.795 | I12: 3933.364 | J12: 2655.586 | K12: 2189.083 | L12: 1992.42 | M12: 1929.111 | N12: 2786.031 | O12: 877.042 | P12: 5236.806 | Q12: 3193.116 | R12: =SUM(C12:Q12) -> 40379.633 | V12: 501 | W12: 0.053 | X12: 0.054 | Y12: 0.054 | Z12: 0.048 | AA12: 0.049 | AB12: 0.06 | AC12: 0.128 | AD12: 0.185 | AE12: 0.111 | AJ12: XXX | AK12: XXX | AL12: XXX | AM12: XXX | AN12: XXX | AP12: 45159 | AQ12: 45215 | AR12: 45215 | AS12: 261 | AT12: 2998.76 | AU12: 1720.47 | AV12: 4.77 | AW12: =ROUND((AU12+AV12)/AS12,2) -> 6.61 | AX12: 1272.98 | AY12: 0.54 | BB12: USO REC. HÍDR. ESGOTO | BI12: 3.43 | BK12: USO REC. HÍDR. ESGOTO | BR12: 3.36 | BU12: GÁS: HÁ 2 TANQUES DE 200 KG CADA. 1KG COMPRADO É IGUAL A 2,5M3 CONSUMIDOS. ESSE VALOR É CORRIGIDO A CADA ABASTECIMENTO. 2ª VARIÁVEL DA FÓRMULA (COLUNA "CONSUMO M3"): VALOR É IGUAL A 2,5 X O PREÇO UNITÁRIO DO QUILO, QUE SERÁ VERIFICADO NO ÚLTIMO ABASTECIMENTO FEITO
A13: 45166 | B13: ÁGUA | C13: 2396.08 | D13: 0 | E13: 5923.725 | F13: 3855.312 | G13: 1721.456 | H13: 1799.713 | I13: 3950.691 | J13: 2666.401 | K13: 2201.556 | L13: 2001.809 | M13: 1933.433 | N13: 2795.101 | O13: 879.561 | P13: 5244.122 | Q13: 3209.97 | R13: =SUM(C13:Q13) -> 40578.93 | V13: 502 | W13: 0.051 | X13: 0.047 | Y13: 0.051 | Z13: 0.045 | AA13: 0.047 | AB13: 0.056 | AC13: 0.069 | AD13: 0.057 | AE13: 0.059 | AJ13: XXX | AK13: XXX | AL13: XXX | AM13: XXX | AN13: XXX | AP13: 45189 | AQ13: 45245 | AR13: 45245 | AS13: 242 | AT13: =AU13+AV13+AX13+AY13 -> 2684.4 | AU13: 1539.74 | AV13: 4.87 | AW13: =ROUND((AU13+AV13)/AS13,2) -> 6.38 | AX13: 1139.24 | AY13: 0.55 | BB13: TOTAL | BI13: =BI10+BI11+BI12 -> 650.78 | BK13: TOTAL | BR13: =BR10+BR11+BR12 -> 12389.142 | BU13: GÁS DO 201: TEM UM MEDIDOR A PARTE. NO APTº A MEDIÇÃO GERALMENTE É ZERO, PORQUE TEM FOGÃO ELÉTRICO
A14: 45197 | B14: ÁGUA | C14: 2416.782 | D14: 0 | E14: 5955.074 | F14: 3872.337 | G14: 1736.355 | H14: 1818.171 | I14: 3967.667 | J14: 2678.981 | K14: 2211.822 | L14: 2017.308 | M14: 1938.571 | N14: 2804.456 | O14: 882.839 | P14: 5251.34 | Q14: 3227.372 | R14: =SUM(C14:Q14) -> 40779.075 | V14: 601 | W14: 0.013 | X14: 0.016 | Y14: 0.014 | Z14: 0.011 | AA14: 0.011 | AB14: 0.022 | AC14: 0.025 | AD14: 0.014 | AE14: 0.017 | AJ14: XXX | AK14: XXX | AL14: XXX | AM14: XXX | AN14: XXX | AP14: 45222 | AQ14: 45275 | AR14: 45275 | AS14: 239 | AT14: =AU14+AV14+AX14+AY14 -> 2634.49 | AU14: 1511.21 | AV14: 4.64 | AW14: =ROUND((AU14+AV14)/AS14,2) -> 6.34 | AX14: 1118.12 | AY14: 0.52 | BB14: LEITURA ERRADA QUE FOI FEITA EM 22/07/25: | BH14: 5021 | BI14: M3 | BK14: LEITURA ATUAL, VERIFIQUEI QUE ESTÁ CORRETA: | BQ14: 5657 | BR14: M3 | BU14: ÁGUA/ESGOTO DA LEITURA DE 20/12/22, MODELO, 3ª VARIÁVEL DA FÓRMULA (COLUNA "CONSUMO M3"): IGUAL AO ESGOTO DINÂMICO ($881,49) MAIS RECURSOS HÍDRICOS ESGOTO ($0,49), ISSO DIVIDIDO POR 15 (CONDÔMINOS + CONDOMÍNIO), TUDO NA CONTA, IGUAL A $58,798, ARREDOND. P/$58,80
A15: 45227 | B15: ÁGUA | C15: 2436.831 | D15: 0 | E15: 5972.821 | F15: 3892.028 | G15: 1750.664 | H15: 1835.107 | I15: 3987.57 | J15: 2690.956 | K15: 2223.174 | L15: 2028.352 | M15: 1943.757 | N15: 2814.368 | O15: 885.629 | P15: 5260.244 | Q15: 3243.387 | R15: =SUM(C15:Q15) -> 40964.888 | V15: 602 | W15: 0.045 | X15: 0.076 | Y15: 0.075 | Z15: 0.087 | AA15: 0.059 | AB15: 0.093 | AC15: 0.006 | AD15: 0.021 | AE15: 0.003 | AJ15: XXX | AK15: XXX | AL15: XXX | AM15: XXX | AN15: XXX | AP15: 45253 | AQ15: 45306 | AR15: 45306 | AS15: 246 | AT15: =AU15+AV15+AX15+AY15 -> 2749.91 | AU15: 1577.79 | AV15: 4.25 | AW15: =ROUND((AU15+AV15)/AS15,2) -> 6.43 | AX15: 1167.39 | AY15: 0.48 | BB15: LEITURA CORRETA DE 22/07/25: | BH15: 5362 | BI15: M3 | BK15: LEITURA ANTERIOR CORRETA: | BQ15: =BH15 -> 5362 | BR15: M3 | BU15: CONSUMO DE ÁGUA DO CONDOMÍNIO: RAZOÁVEL ENTRE 20 E 40 M3. MENOS DE 20M3 OU MAIS DE 40M3: UMA DAS 2 LEITURAS PODE ESTAR ERRADA
A16: 45258 | B16: ÁGUA | C16: 2455.727 | D16: 0 | E16: 6004.368 | F16: 3909.588 | G16: 1769.361 | H16: 1854.208 | I16: 4010.335 | J16: 2703.906 | K16: 2237.708 | L16: 2043.882 | M16: 1952.156 | N16: 2825.211 | O16: 888.719 | P16: 5262.031 | Q16: 3262.162 | R16: =SUM(C16:Q16) -> 41179.362 | V16: 701 | W16: 0.057 | X16: 0.056 | Y16: 0.061 | Z16: 0.057 | AA16: 0.064 | AB16: 0.07 | AC16: 0.059 | AD16: 0.056 | AE16: 0.059 | AJ16: XXX | AK16: XXX | AL16: XXX | AM16: XXX | AN16: XXX | AP16: 45281 | AQ16: 45337 | AR16: 45337 | AS16: 243 | AT16: =AU16+AV16+AX16+AY16 -> 2699.88 | AU16: 1549.26 | AV16: 3.9 | AW16: =ROUND((AU16+AV16)/AS16,2) -> 6.39 | AX16: 1146.28 | AY16: 0.44 | BB16: LEITURA ANTERIOR: | BH16: 5001 | BI16: M3 | BK16: CONSUMO CORRETO: | BQ16: =BQ14-BQ15 -> 295 | BR16: M3 | BU16: ANOTAR NO FINAL DA TABELA "RESUMO DOS LANÇAMENTOS (RECEITAS/DESPESAS) O SALDO DE CRÉDITO OU DÉBITO DE DIFERENÇA DE LEITURA (DIFERENÇA DE CONSUMO DE ÁGUA DO CONDOMÍNIO FORA DA PREVISÃO)
A17: 45288 | B17: ÁGUA | C17: 2474.42 | D17: 0 | E17: 6053.424 | F17: 3931.077 | G17: 1784.135 | H17: 1871.797 | I17: 4032.631 | J17: 2715.053 | K17: 2250.844 | L17: 2059.568 | M17: 1968.013 | N17: 2836.379 | O17: 891.618 | P17: 5265.855 | Q17: 3281.035 | R17: =SUM(C17:Q17) -> 41415.849 | V17: 702 | W17: 0.023 | X17: 0.026 | Y17: 0.029 | Z17: 0.027 | AA17: 0.028 | AB17: 0.031 | AC17: 0.034 | AD17: 0.026 | AE17: 0.031 | AJ17: XXX | AK17: XXX | AL17: XXX | AM17: XXX | AN17: XXX | AP17: 45313 | AQ17: 45366 | AR17: 45366 | AS17: 293 | AT17: =AU17+AV17+AX17+AY17 -> 3689.84 | AU17: 2117.99 | AV17: 4.15 | AW17: =ROUND((AU17+AV17)/AS17,2) -> 7.24 | AX17: 1567.23 | AY17: 0.47 | BB17: CONSUMO CORRETO: | BH17: =BH15-BH16 -> 361 | BI17: M3
A18: 45319 | B18: ÁGUA | C18: 2491.821 | D18: 0 | E18: 6102.368 | F18: 3953.12 | G18: 1800.569 | H18: 1885.724 | I18: 4058.137 | J18: 2726.861 | K18: 2265.914 | L18: 2075.591 | M18: 1994.272 | N18: 2850.035 | O18: 894.558 | P18: 5267.996 | Q18: 3300.08 | R18: =SUM(C18:Q18) -> 41667.046 | V18: 801 | W18: 0.02 | X18: 0.017 | Y18: 0.015 | Z18: 0.014 | AA18: 0.016 | AB18: 0.024 | AC18: 0.021 | AD18: 0.022 | AE18: 0.02 | AJ18: XXX | AK18: XXX | AL18: XXX | AM18: XXX | AN18: XXX | AP18: 45342 | AQ18: 45397 | AR18: 45397 | AS18: 251 | AT18: =AU18+AV18+AX18+AY18 -> 2951.83 | AU18: 1693.72 | AV18: 4.3 | AW18: =ROUND((AU18+AV18)/AS18,2) -> 6.77 | AX18: 1253.32 | AY18: 0.49
A19: 45350 | B19: ÁGUA | C19: 2505.809 | D19: 0 | E19: 6151.25 | F19: 3971.944 | G19: 1815.415 | H19: 1905.788 | I19: 4084.603 | J19: 2737.65 | K19: 2281.466 | L19: 2090.551 | M19: 2001.276 | N19: 2861.248 | O19: 898.348 | P19: 5268.242 | Q19: 3317.755 | R19: =SUM(C19:Q19) -> 41891.345 | V19: 802 | W19: 0.056 | X19: 0.049 | Y19: 0.037 | Z19: 0.036 | AA19: 0.041 | AB19: 0.066 | AC19: 0.062 | AD19: 0.052 | AE19: 0.062 | AJ19: XXX | AK19: XXX | AL19: XXX | AM19: XXX | AN19: XXX | AP19: 45370 | AQ19: 45427 | AR19: 45427 | AS19: 256 | AT19: =AU19+AV19+AX19+AY19 -> 3039.17 | AU19: 1743.28 | AV19: 5.3 | AW19: =ROUND((AU19+AV19)/AS19,2) -> 6.83 | AX19: 1289.99 | AY19: 0.6 | BB19: TARIFAS DA LEITURA DE 22/07/2025 APÓS SER CORRIGIDA (NÃO FOI CORRIGIDA ATÉ 27/08/25) | BK19: TARIFAS DA LEITURA DE 22/08/25 APÓS A LEITURA DE 22/07/25 SER CORRIGIDA (NÃO FOI CORRIGIDA ATÉ 27/08/25)
A20: 45379 | B20: ÁGUA | C20: 2523.908 | D20: 0 | E20: 6192.33 | F20: 3991.919 | G20: 1830.717 | H20: 1918.385 | I20: 4101.951 | J20: 2748.753 | K20: 2297.261 | L20: 2101.516 | M20: 2023.642 | N20: 2874.74 | O20: 903.365 | P20: 5269.756 | Q20: 3336.855 | R20: =SUM(C20:Q20) -> 42115.098 | V20: TOTAL | W20: =SUM(W4:W19) -> 0.927 | X20: =SUM(X4:X19) -> 0.999 | Y20: =SUM(Y4:Y19) -> 1 | Z20: =SUM(Z4:Z19) -> 1 | AA20: =SUM(AA4:AA19) -> 1 | AB20: =SUM(AB4:AB19) -> 1 | AC20: =SUM(AC4:AC19) -> 1 | AD20: =SUM(AD4:AD19) -> 1 | ... AF20: =SUM(AF4:AF19) -> 0 | AJ20: XXX | AK20: XXX | AL20: XXX | AM20: XXX | AN20: XXX | AP20: 45400 | AQ20: 45460 | AR20: 45460 | AS20: 289 | AT20: =AU20+AV20+AX20+AY20 -> 3649.9 | AU20: 2094.6 | AV20: 4.79 | AW20: =ROUND((AU20+AV20)/AS20,2) -> 7.26 | AX20: 1549.97 | AY20: 0.54 | BB20: FX. CONSUMO M3 | BC20: CONSUMO DA FX. EM M3 | BD20: VOLUME TOTAL | BE20: R$/M3 DE ÁGUA | BF20: VR. DA ÁGUA | BG20: R$/M3 DE ESGOTO | BH20: VR. DO ESGOTO | BI20: SUBTOTAL | BK20: FX. CONSUMO M3 | BL20: CONSUMO DA FX. EM M3 | BM20: VOLUME TOTAL | BN20: R$/M3 DE ÁGUA | BO20: VR. DA ÁGUA | BP20: R$/M3 DE ESGOTO | BQ20: VR. DO ESGOTO | BR20: SUBTOTAL
A21: 45411 | B21: ÁGUA | C21: 2546.976 | D21: 0 | E21: 6237.3 | F21: 4018.728 | G21: 1849.796 | H21: 1928.603 | I21: 4117.224 | J21: 2758.828 | K21: 2320.094 | L21: 2124.267 | M21: 2052.455 | N21: 2893.032 | O21: 909.32 | P21: 5269.944 | Q21: 3353.903 | R21: =SUM(C21:Q21) -> 42380.47 | V21: CONFERÊNCIA | W21: 1 | X21: 1 | Y21: 1 | Z21: 1 | AA21: 1 | AB21: 1 | AC21: 1 | AD21: 1 | AE21: 1 | AF21: 1 | AJ21: XXX | AK21: XXX | AL21: XXX | AM21: XXX | AN21: XXX | AP21: 45433 | AQ21: 45488 | AR21: 45488 | AS21: 302 | AT21: =AU21+AV21+AX21+AY21 -> 3935.17 | AU21: 2258.49 | AV21: 4.88 | AW21: =ROUND((AU21+AV21)/AS21,2) -> 7.49 | AX21: 1671.25 | AY21: 0.55 | BB21: FIXA | BF21: 316.4 | BH21: 233.94 | BI21: =BF21+BH21 -> 550.34 | BK21: FIXA | BO21: 316.4 | BQ21: 233.94 | BR21: =BO21+BQ21 -> 550.34
A22: 45441 | B22: ÁGUA | C22: 2567.926 | D22: 0 | E22: 6280.362 | F22: 4045.151 | G22: 1871.71 | H22: 1943.225 | I22: 4138.443 | J22: 2765.393 | K22: 2329.702 | L22: 2140.097 | M22: 2061.531 | N22: 2916.945 | O22: 914.484 | P22: 5274.594 | Q22: 3368.671 | R22: =SUM(C22:Q22) -> 42618.234 | V22: CONFERÊNCIA | W22: =W20-W21 -> -0.073 | X22: =X20-X21 -> -0.001 | Y22: =Y20-Y21 -> 0 | Z22: =Z20-Z21 -> 0 | AA22: =AA20-AA21 -> 0 | AB22: =AB20-AB21 -> 0 | AC22: =AC20-AC21 -> 0 | AD22: =AD20-AD21 -> 0 | ... AF22: =AF20-AF21 -> -1 | AJ22: XXX | AK22: XXX | AL22: XXX | AM22: XXX | AN22: XXX | AP22: 45463 | AQ22: 45519 | AR22: 45519 | AS22: 287 | AT22: =AU22+AV22+AX22+AY22 -> 3238.72 | AU22: 1852.3 | AV22: 12.45 | AW22: =ROUND((AU22+AV22)/AS22,2) -> 6.5 | AX22: 1370.67 | AY22: 3.3 | BB22: 0 A 5 | BC22: 5 | BD22: 70 | BE22: 2.34 | BF22: =ROUND(BD22*BE22,2) -> 163.8 | BG22: 1.73 | BH22: =BD22*BG22 -> 121.1 | BI22: =BF22+BH22 -> 284.9 | BK22: 0 A 5 | BL22: 5 | BM22: 70 | BN22: 2.34 | BO22: =ROUND(BM22*BN22,2) -> 163.8 | BP22: 1.73 | BQ22: =BM22*BP22 -> 121.1 | BR22: =BO22+BQ22 -> 284.9
A23: 45471 | B23: ÁGUA | C23: 2587.661 | D23: 0 | E23: 6316.765 | F23: 4075.057 | G23: 1898.116 | H23: 1962.961 | I23: 4159.113 | J23: 2774.914 | K23: 2342.361 | L23: 2156.088 | M23: 2065.768 | N23: 2930.577 | O23: 918.504 | P23: 5278.061 | Q23: 3382.209 | R23: =SUM(C23:Q23) -> 42848.155 | AJ23: XXX | AK23: XXX | AL23: XXX | AM23: XXX | AN23: XXX | AP23: 45495 | AQ23: 45551 | AR23: 45551 | AS23: 276 | AT23: =AU23+AV23+AX23+AY23 -> 3395.64 | AU23: 1941.5 | AV23: 13.81 | AW23: =ROUND((AU23+AV23)/AS23,2) -> 7.08 | AX23: 1436.67 | AY23: 3.66 | AZ23: CONTA ORIGINAL DE 22/07/24, C/FATURAMENTO REALIZADO PELA MÉDIA DE CONSUMO (VIDRO EMBAÇADO/SUJO) | BB23: 5 A 10 | BC23: 5 | BD23: 70 | BE23: 4.987 | BF23: =ROUND(BD23*BE23,2) -> 349.09 | BG23: 3.69 | BH23: =BD23*BG23 -> 258.3 | BI23: =BF23+BH23 -> 607.39 | BK23: 5 A 10 | BL23: 5 | BM23: 70 | BN23: 4.987 | BO23: =ROUND(BM23*BN23,2) -> 349.09 | BP23: 3.69 | BQ23: =BM23*BP23 -> 258.3 | BR23: =BO23+BQ23 -> 607.39
A24: 45501 | B24: ÁGUA | C24: 2606.608 | D24: 0 | E24: 6367.535 | F24: 4100.681 | G24: 1917.329 | H24: 1980.374 | I24: 4187.751 | J24: 2789.214 | K24: 2356.703 | L24: 2188.661 | M24: 2069.694 | N24: 2942.168 | O24: 922.149 | P24: 5281.666 | Q24: 3394.571 | R24: =SUM(C24:Q24) -> 43105.104 | AJ24: XXX | AK24: XXX | AL24: XXX | AM24: XXX | AN24: XXX | AP24: 45526 | AQ24: 45580 | AR24: 45580 | AS24: 287 | AT24: =AU24+AV24+AX24+AY24 -> 3616.11 | AU24: 2069.39 | AV24: 12.18 | AW24: =ROUND((AU24+AV24)/AS24,2) -> 7.25 | AX24: 1531.31 | AY24: 3.23 | BB24: 10 A 15 | BC24: 5 | BD24: 70 | BE24: 7.727 | BF24: =ROUND(BD24*BE24,2) -> 540.89 | BG24: 5.718 | BH24: =BD24*BG24 -> 400.26 | BI24: =BF24+BH24 -> 941.15 | BK24: 10 A 15 | BL24: 5 | BM24: 70 | BN24: 7.727 | BO24: =ROUND(BM24*BN24,2) -> 540.89 | BP24: 5.718 | BQ24: =BM24*BP24 -> 400.26 | BR24: =BO24+BQ24 -> 941.15
A25: 45532 | B25: ÁGUA | C25: 2626.524 | D25: 0 | E25: 6414.423 | F25: 4134.323 | G25: 1939.863 | H25: 1998.727 | I25: 4218.262 | J25: 2808.315 | K25: 2372.412 | L25: 2225.998 | M25: 2074.397 | N25: 2956.722 | O25: 925.675 | P25: 5288.84 | Q25: 3407.617 | R25: =SUM(C25:Q25) -> 43392.098 | AJ25: XXX | AK25: XXX | AL25: XXX | AM25: XXX | AN25: XXX | AP25: 45495 | AQ25: 45551 | AR25: 45551 | AS25: 297 | AT25: =AU25+AV25+AX25+AY25 -> 3837.53 | AU25: 2195.46 | AV25: 13.81 | AW25: =ROUND((AU25+AV25)/AS25,2) -> 7.44 | AX25: 1624.6 | AY25: 3.66 | AZ25: DIFERENÇA DE VALOR REF. À CONTA RECALCULADA EM 04/09/24 NA AGÊNCIA DA COPASA (R. TREMEDAL), POIS O FATURAMENTO DA ANTERIOR FOI REALIZADO PELA MÉDIA DE CONSUMO (VIDRO EMBAÇADO/SUJO) | BB25: 15 A 20 | BC25: 5 | BD25: 70 | BE25: 10.549 | BF25: =ROUND(BD25*BE25,2) -> 738.43 | BG25: 7.806 | BH25: =BD25*BG25 -> 546.42 | BI25: =BF25+BH25 -> 1284.85 | BK25: 15 A 20 | BL25: 5 | BM25: 70 | BN25: 10.549 | BO25: =ROUND(BM25*BN25,2) -> 738.43 | BP25: 7.806 | BQ25: =BM25*BP25 -> 546.42 | BR25: =BO25+BQ25 -> 1284.85
A26: 45563 | B26: ÁGUA | C26: 2651.145 | D26: 0 | E26: 6460.245 | F26: 4165.149 | G26: 1967.666 | H26: 2017.377 | I26: 4243.84 | J26: 2831.729 | K26: 2387.454 | L26: 2241.497 | M26: 2079.757 | N26: 2967.437 | O26: 929.334 | P26: 5295.181 | Q26: 3421.916 | R26: =SUM(C26:Q26) -> 43659.727 | AJ26: XXX | AK26: XXX | AL26: XXX | AM26: XXX | AN26: XXX | AP26: 45555 | AQ26: 45614 | AR26: 45614 | AS26: 191 | AT26: =AU26+AV26+AX26+AY26 -> 2015.8 | AU26: 1149.43 | AV26: 12.5 | AW26: =ROUND((AU26+AV26)/AS26,2) -> 6.08 | AX26: 850.56 | AY26: 3.31 | BB26: 20 A 40 | BC26: ??? | BD26: =361-280 -> 81 | BE26: 13.418 | BF26: =ROUND(BD26*BE26,2) -> 1086.86 | BG26: 9.929 | BH26: =BD26*BG26 -> 804.249 | BI26: =BF26+BH26 -> 1891.109 | BK26: 20 A 40 | BL26: ??? | BM26: 15 | BN26: 13.418 | BO26: =ROUND(BM26*BN26,2) -> 201.27 | BP26: 9.929 | BQ26: =BM26*BP26 -> 148.935 | BR26: =BO26+BQ26 -> 350.205
A27: 45593 | B27: ÁGUA | C27: 2674.494 | D27: 0 | E27: 6502.896 | F27: 4197.01 | G27: 1993.943 | H27: 2037.885 | I27: 4268.178 | J27: 2853.405 | K27: 2401.423 | L27: 2245.133 | M27: 2084.641 | N27: 2978.578 | O27: 933.19 | P27: 5300.14 | Q27: 3435.194 | R27: =SUM(C27:Q27) -> 43906.11 | AJ27: XXX | AK27: XXX | AL27: XXX | AM27: XXX | AN27: XXX | AP27: 45587 | AQ27: 45642 | AR27: 45642 | AS27: 294 | AT27: =AU27+AV27+AX27+AY27 -> 3789.21 | AU27: 2157.64 | AV27: 28.18 | AW27: =ROUND((AU27+AV27)/AS27,2) -> 7.43 | AX27: 1596.62 | AY27: 6.77 | BB27: 40 A 60 | BK27: 40 A 60
A28: 45624 | B28: ÁGUA | C28: 2694.831 | D28: 0 | E28: 6540.498 | F28: 4218.168 | G28: 2018.795 | H28: 2058.898 | I28: 4289.126 | J28: 2873.857 | K28: 2416.056 | L28: 2249.807 | M28: 2089.656 | N28: 2989.712 | O28: 936.589 | P28: 5302.492 | Q28: 3464.005 | R28: =SUM(C28:Q28) -> 44142.49 | AJ28: XXX | AK28: XXX | AL28: XXX | AM28: XXX | AN28: XXX | AP28: 45618 | AQ28: 45672 | AR28: 45672 | AS28: 274 | AT28: =AU28+AV28+AX28+AY28 -> 3366.67 | AU28: 1921.67 | AV28: 18.54 | AW28: =ROUND((AU28+AV28)/AS28,2) -> 7.08 | AX28: 1422.01 | AY28: 4.45 | BB28: SOMA | BC28: ??? | BD28: =SUM(BD22:BD27) -> 361 | BF28: =SUM(BF21:BF27) -> 3195.47 | BH28: =SUM(BH21:BH27) -> 2364.269 | BI28: =SUM(BI21:BI27) -> 5559.739 | BK28: SOMA | BL28: ??? | BM28: =SUM(BM22:BM27) -> 295 | BO28: =SUM(BO21:BO27) -> 2309.88 | BQ28: =SUM(BQ21:BQ27) -> 1708.955 | BR28: =SUM(BR21:BR27) -> 4018.835
A29: 45654 | B29: ÁGUA | C29: 2714.766 | D29: 0 | E29: 6586.864 | F29: 4237.037 | G29: 2045.323 | H29: 2081.342 | I29: 4311.653 | J29: 2888.889 | K29: 2430.452 | L29: 2256.901 | M29: 2093.591 | N29: 2999.657 | O29: 940.243 | P29: 5309.751 | Q29: 3475.724 | R29: =SUM(C29:Q29) -> 44372.193 | U29: MENSALMENTE: | AJ29: XXX | AK29: XXX | AL29: XXX | AM29: XXX | AN29: XXX | AP29: 45647 | AQ29: 45705 | AR29: 45705 | AS29: 220 | AT29: =AU29+AV29+AX29+AY29 -> 2446.4 | AU29: 1386.48 | AV29: 27.37 | AW29: =ROUND((AU29+AV29)/AS29,2) -> 6.43 | AX29: 1025.97 | AY29: 6.58 | BB29: USO REC. HÍDR. ÁGUA | BI29: ??? | BK29: USO REC. HÍDR. ÁGUA | BR29: ???
A30: 45686 | B30: ÁGUA | C30: 2733.035 | D30: 0 | E30: 6634.611 | F30: 4252.168 | G30: 2074.272 | H30: 2102.808 | I30: 4339.623 | J30: 2905.589 | K30: 2446.344 | L30: 2261.718 | M30: 2115.941 | N30: 3014.502 | O30: 945.558 | P30: 5314.469 | Q30: 3488.552 | R30: =SUM(C30:Q30) -> 44629.19 | U30: ELIMINAR DA TABELA "MEDIÇÕES E TABELAS" A 1ª COLUNA DATADA | AJ30: XXX | AK30: XXX | AL30: XXX | AM30: XXX | AN30: XXX | AP30: 45679 | AQ30: 45733 | AR30: 45733 | AS30: 292 | AT30: =AU30+AV30+AX30+AY30 -> 3908.29 | AU30: 2226.75 | AV30: 27.42 | AW30: =ROUND((AU30+AV30)/AS30,2) -> 7.72 | AX30: 1647.53 | AY30: 6.59 | BB30: USO REC. HÍDR. ESGOTO | BI30: ??? | BK30: USO REC. HÍDR. ESGOTO | BR30: ???
A31: 45716 | B31: ÁGUA | C31: 2750.222 | D31: 0 | E31: 6676.777 | F31: 4274.198 | G31: 2099.177 | H31: 2124.266 | I31: 4372.04 | J31: 2922.633 | K31: 2460.491 | L31: 2265.593 | M31: 2139.219 | N31: 3027.339 | O31: 951.566 | P31: 5317.16 | Q31: 3500.965 | R31: =SUM(C31:Q31) -> 44881.646 | U31: COPIAR A ÚLTIMA COLUNA DAQUELA TABELA PARA A PRESENTE PLANILHA | AJ31: XXX | AK31: XXX | AL31: XXX | AM31: XXX | AN31: XXX | AP31: 45708 | AQ31: 45762 | AR31: 45762 | AS31: 266 | AT31: =AU31+AV31+AX31+AY31 -> 3438.61 | AU31: 1960.92 | AV31: 21.73 | AW31: =ROUND((AU31+AV31)/AS31,2) -> 7.45 | AX31: 1450.74 | AY31: 5.22 | BB31: TOTAL | BI31: =BI28 -> 5559.739 | BK31: TOTAL | BR31: =BR28 -> 4018.835
A32: 45745 | B32: ÁGUA | C32: 2769.255 | D32: 0 | E32: 6718.496 | F32: 4292.982 | G32: 2126.985 | H32: 2142.016 | I32: 4405.98 | J32: 2937.697 | K32: 2471.101 | L32: 2269.266 | M32: 2161.24 | N32: 3039.59 | O32: 957.542 | P32: 5321.136 | Q32: 3512.612 | R32: =SUM(C32:Q32) -> 45125.898 | AJ32: XXX | AK32: XXX | AL32: XXX | AM32: XXX | AN32: XXX | AP32: 45740 | AQ32: 45792 | AR32: 45792 | AS32: 289 | AT32: =AU32+AV32+AX32+AY32 -> 3916.52 | AU32: 2229.37 | AV32: 30.45 | AW32: =ROUND((AU32+AV32)/AS32,2) -> 7.82 | AX32: 1649.38 | AY32: 7.32 | AZ32: ESTA CONTA FOI REEMITIDA EM 04/04/25 APÓS SOLICITAÇAO DE 31/03/25. A ORIGINAL DE 24/03/25 ESTAVA COM C/FATURAMENTO REALIZADO PELA MÉDIA DE CONSUMO (VIDRO EMBAÇADO/SUJO)
A33: 45775 | B33: ÁGUA | C33: 2792.975 | D33: 0 | E33: 6760.554 | F33: 4313.315 | G33: 2154.435 | H33: 2162.217 | I33: 4438.931 | J33: 2952.925 | K33: 2483.245 | L33: 2276.685 | M33: 2184.038 | N33: 3055.548 | O33: 964.436 | P33: 5327.134 | Q33: 3527.734 | R33: =SUM(C33:Q33) -> 45394.172 | AJ33: XXX | AK33: XXX | AL33: XXX | AM33: XXX | AN33: XXX | AP33: 45771 | AQ33: 45824 | AR33: 45824 | AS33: 244 | AT33: =AU33+AV33+AX33+AY33 -> 3043.18 | AU33: 1728.85 | AV33: 28.49 | AW33: =ROUND((AU33+AV33)/AS33,2) -> 7.2 | AX33: 1279 | AY33: 6.84
A34: 45805 | B34: ÁGUA | C34: 2819.356 | D34: 0 | E34: 6808.096 | F34: 4333.909 | G34: 2181.332 | H34: 2184.799 | I34: 4479.234 | J34: 2966.677 | K34: 2497.318 | L34: 2281.158 | M34: 2201.411 | N34: 3069.081 | O34: 970.584 | P34: 5331.826 | Q34: 3541.107 | R34: =SUM(C34:Q34) -> 45665.888 | AJ34: XXX | AK34: XXX | AL34: XXX | AM34: XXX | AN34: XXX | AP34: 45800 | AQ34: 45853 | AR34: 45853 | AS34: 309 | AT34: =AU34+AV34+AX34+AY34 -> 4380.41 | AU34: 2497.73 | AV34: 28 | AW34: =ROUND((AU34+AV34)/AS34,2) -> 8.17 | AX34: 1847.96 | AY34: 6.72 | AZ34: ESTA CONTA FOI REEMITIDA EM 27/05/25 APÓS SOLICITAÇAO DE MESMA DATA. A ORIGINAL DE 23/05/25 ESTAVA COM C/FATURAMENTO REALIZADO PELA MÉDIA DE CONSUMO (VIDRO EMBAÇADO/SUJO)
A35: 45836 | B35: ÁGUA | C35: 2845.108 | D35: 0 | E35: 6853.487 | F35: 4352.74 | G35: 2209.487 | H35: 2209.08 | I35: 4542.657 | J35: 2982.973 | K35: 2511.29 | L35: 2286.864 | M35: 2220.498 | N35: 3084.382 | O35: 976.98 | P35: 5335.117 | Q35: 3551.921 | R35: =SUM(C35:Q35) -> 45962.584 | AJ35: XXX | AK35: XXX | AL35: XXX | AM35: XXX | AN35: XXX | AP35: 45832 | AQ35: 45887 | AR35: 45887 | AS35: 288 | AT35: =AU35+AV35+AX35+AY35 -> 3870.33 | AU35: 2215.95 | AV35: 12.24 | AW35: =ROUND((AU35+AV35)/AS35,2) -> 7.74 | AX35: 1639.45 | AY35: 2.69 | AZ35: O CONSUMO TOTAL EM M3 E O VALOR DO ESGOTO DESTA CONTA FORAM TAMBÉM USADOS PARA O FIM DO RATEIO REFERENTE A 08/2025. O TOTAL DA LEITURA DE 24/06/25 FOI USADO (E DEPOIS ZERADO) PARA A APURAÇÃO DO CONSUMO DO CONDOMÍNIO DA REFERÊNCIA 08/2025, UMA VEZ QUE A LEITURA NA CONTA DA COPASA (DE 22/07/25) ESTÁ INCORRETA (PARA MENOR!!!), E QUE NÃO FOI ATENDIDA ATÉ O DIA 08/08/25 MINHA SOLICITAÇÃO DE CORREÇÃO DA LEITURA JUNTO À COPASA.
A36: 45866 | B36: ÁGUA | C36: 2859.658 | D36: 0 | E36: 6883.806 | F36: 4371.664 | G36: 2237.09 | H36: 2236.475 | I36: 4599.043 | J36: 2998.207 | K36: 2526.018 | L36: 2290.725 | M36: 2233.459 | N36: 3100.83 | O36: 983.732 | P36: 5340.984 | Q36: 3567.961 | R36: =SUM(C36:Q36) -> 46229.652 | AJ36: XXX | AK36: XXX | AL36: XXX | AM36: XXX | AN36: XXX | AP36: 45860 | AQ36: 45915 | AR36: CTª SUBSTITUÍDA | AS36: 20 | AT36: =AU36+AV36+AX36+AY36 -> 650.78 | AU36: 363.2 | AV36: 15.61 | AW36: =ROUND((AU36+AV36)/AS36,2) -> 18.94 | AX36: 268.54 | AY36: 3.43 | AZ36: ESTA CONTA FOI REEMITIDA EM XX/XX/25 APÓS SOLICITAÇAO DE MESMA DATA. A ORIGINAL DE 22/07/25 ESTAVA COM C/ERRO DE LEITURA, TALVEZ PELO VIDRO ESTAR EMBAÇADO (PEDI NA AGÊNCIA DA COPASA NA R. CURITIBA, +-1135, CORREÇÃO DA LEITURA E SUBSTITUIÇÃO DO VIDRO DO HIDRÔMETRO, QUE ESTÁ DIFICULTANDO A LEITURA)
A37: 45897 | B37: ÁGUA | C37: 2881.573 | D37: 0 | E37: 6907.842 | F37: 4394.079 | G37: 2266.687 | H37: 2266.206 | I37: 4658.325 | J37: 3014.01 | K37: 2539.95 | L37: 2295.441 | M37: 2255.938 | N37: 3117.38 | O37: 991.377 | P37: 5346.02 | Q37: 3582.467 | R37: =SUM(C37:Q37) -> 46517.295 | AJ37: =[1]LANÇTºS!R27 -> 45901 | AK37: 102.13 | AM37: 570.56 | AP37: 45891 | AQ37: 45945 | AR37: CTª SUBSTITUÍDA | AS37: =BM28 -> 295 | AT37: =AU37+AV37+AX37+AY37 -> 4018.835 | AU37: =BO28 -> 2309.88 | AV37: 0 | AW37: =ROUND((AU37+AV37)/AS37,2) -> 7.83 | AX37: =BQ28 -> 1708.955 | AY37: 0 | AZ37: OS DADOS AQUI LANÇADOS SÃO HIPOTÉTICOS, POIS ESTA CONTA ESTÁ SENDO POR MIM QUESTIONADA, CONFORME TABELAS À DIREITA, EM VISTA DE NÃO TER SIDO AINDA CORRIGIDA A CONTA ANTERIOR
A38: 45928 | B38: ÁGUA | C38: 2901.993 | D38: 0 | E38: 6935.39 | F38: 4415.237 | G38: 2299.257 | H38: 2299.648 | I38: 4680.888 | J38: 3029.976 | K38: 2555.083 | L38: 2299.55 | M38: 2277.98 | N38: 3135.365 | O38: 999.908 | P38: 5350.331 | Q38: 3593.277 | R38: =SUM(C38:Q38) -> 46773.883 | AJ38: XXX | AK38: XXX | AL38: XXX | AM38: XXX | AN38: XXX | AP38: 45860 | AQ38: 45915 | AR38: 45912 | AS38: 311 | AT38: =AU38+AV38+AX38+AY38 -> 4411.43 | AU38: 2524.57 | AV38: 15.61 | AW38: =ROUND((AU38+AV38)/AS38,2) -> 8.17 | AX38: 1867.82 | AY38: 3.43 | AZ38: NOVA CONTA OBTIDA EM 02/09/25, SUBSTITUINDO A ANTERIOR, QUE TINHA ERRO DE LEITURA (NÃO FOI USADA P/CALCULAR RATEIOS)
A39: 45958 | B39: ÁGUA | C39: 2922.166 | D39: 0 | E39: 6945.799 | F39: 4433.945 | G39: 2332.998 | H39: 2334.054 | I39: 4702.757 | J39: 3044.133 | K39: 2568.217 | L39: 2302.894 | M39: 2303.538 | N39: 3152.257 | O39: 1007.78 | P39: 5354.332 | Q39: 3603.907 | R39: =SUM(C39:Q39) -> 47008.777 | U39: MENSALMENTE: | AJ39: XXX | AK39: XXX | AL39: XXX | AM39: XXX | AN39: XXX | AP39: 45891 | AQ39: 45945 | AR39: 45945 | AS39: 345 | AT39: =AU39+AV39+AX39+AY39 -> 5204.82 | AU39: 2980.78 | AV39: 15.28 | AW39: =ROUND((AU39+AV39)/AS39,2) -> 8.68 | AX39: 2205.4 | AY39: 3.36 | AZ39: NOVA CONTA OBTIDA EM 02/09/25, SUBSTITUINDO A ANTERIOR, QUE TINHA ERRO DE LEITURA (NÃO FOI USADA P/CALCULAR RATEIOS)
A40: 45988 | B40: ÁGUA | C40: 2943.512 | D40: 0 | E40: 6968.752 | F40: 4454.109 | G40: 2367.015 | H40: 2371.531 | I40: 4725.655 | J40: 3058.525 | K40: 2582.062 | L40: 2306.115 | M40: 2320.802 | N40: 3171.152 | O40: 1015.935 | P40: 5359.148 | Q40: 3615.872 | R40: =SUM(C40:Q40) -> 47260.185 | U40: ELIMINAR DA TABELA "MEDIÇÕES E TABELAS" A 1ª LINHA DE ÁGUA E A 1ª DE GÁS | AJ40: 45931 | AK40: 348.46 | AM40: 478.07 | AP40: 45923 | AQ40: 45978 | AR40: 45978 | AS40: 274 | AT40: =AU40+AV40+AX40+AY40 -> 3715.89 | AU40: 2045.31 | AV40: 1.1 | AW40: =ROUND((AU40+AV40)/AS40,2) -> 7.47 | AX40: 1669.24 | AY40: 0.24 | AZ40: NOVA CONTA OBTIDA EM 02/09/25, SUBSTITUINDO A ANTERIOR, QUE TINHA ERRO DE LEITURA (NÃO FOI USADA P/CALCULAR RATEIOS)
...

Sheet MEDIÇÕES E TABELAS
A1: TABELA 1 | D1: (FORAM BLOQUEADAS DIVERSAS CÉLULAS DESTA PLANILHA A PARTIR DE 30/01/26) | M1: (TABELAS 1 E 2 E AS DEMAIS À DIREITA DELAS) | T1: LANÇAMENTOS - ABRIL/2026 | X1: MANTER E ATUALIZAR ESTE TÍTULO, POIS É OBJETO DE FÓRMULA NA PLANILHA "PLAN P COND" | AP1: RATEIOS DE COPASA E SÍNDICO | AV1: COPASA NFFS | BG1: XXXXX | BH1: TARIFAS DA LEITURA DE 22/07/2025 (A QUE ESTAVA INCORRETA ATÉ 27/08/25) | BQ1: TARIFAS DA LEITURA DE 22/08/2025 | BY1: XXXXX | CA1: GÁS (1KG COMPRADO É IGUAL A 2,5M3 CONSUMIDOS)
A2: LEITURA DOS MEDIDORES DE ÁGUA E GÁS (DIA 28 DE CADA MÊS) | T2: TABELA 2 | U2: ÁGUA/ESGOTO, CÁLCULO | Y2: GÁS, CÁLCULO | AP2: MÊS DO LANÇTº | AQ2: COPASA DO COND. A RATEAR (R$) | AR2: COPASA DO COND. A RATEAR - SÓ FÓRMULA | AS2: PARTE DO SÍNDICO A RATEAR (COPASA, GÁS E DESPESAS, EM R$) | AT2: PARTE DO SÍNDICO A RATEAR - SÓ FÓRMULA | AV2: DATAS E CONSUMO | BA2: PARTE REF. À ÁGUA (R$) | BD2: PARTE REF. AO ESGOTO (R$) | BG2: COLUNAS OCULTAS (TABELAS COM SIMULAÇÃO DAS TARIFAS DAS LEITURAS DE 22/07 E 22/08/2025 ANTES DAS CORREÇÕES QUE A COPASA FEZ) | BH2: FX. CONSUMO M3 | BI2: CONSUMO DA FX. EM M3 | BJ2: VOLUME TOTAL | BK2: R$/M3 DE ÁGUA | BL2: VR. DA ÁGUA | BM2: R$/M3 DE ESGOTO | BN2: VR. DO ESGOTO | BO2: SUBTOTAL | BQ2: FX. CONSUMO M3 | BR2: CONSUMO DA FX. EM M3 | BS2: VOLUME TOTAL | BT2: R$/M3 DE ÁGUA | BU2: VR. DA ÁGUA | BV2: R$/M3 DE ESGOTO | BW2: VR. DO ESGOTO | BX2: SUBTOTAL | BY2: COLUNAS OCULTAS (TABELAS COM SIMULAÇÃO DAS TARIFAS DAS LEITURAS DE 22/07 E 22/08/2025 ANTES DAS CORREÇÕES QUE A COPASA FEZ) | CA2: DATA ABASTECTº | CB2: QUANT. (KG) | CC2: PREÇO/KG (= NF) | CD2: TOTAL (R$) | CE2: PREÇO/KG ARREDOND. | CF2: EQUIV. KG PARA M3 | CG2: CUSTO POR M3 (R$)
A3: DATA | B3: ITEM | C3: 201 | D3: 201 GÁS PISC. | E3: 202 | F3: 301 | G3: 302 | H3: 401 | I3: 402 | J3: 501 | K3: 502 | L3: 601 | M3: 602 | N3: 701 | O3: 702 | P3: 801 | Q3: 802 | R3: TOTAL | T3: UNIDADE / ITEM | U3: CONSUMO (NÃO USAR) | V3: % DO CONSUMO TOTAL, PARA CÁLCULO DO VALOR DO ESGOTO A SER COBRADO POR AP | W3: CONSUMO (USAR) | X3: VALOR ÁGUA/ESGOTO (USAR) | Y3: CONSUMO (NÃO USAR) | Z3: CONSUMO (USAR) | AA3: VALOR (USAR) | AC3: % DO CONSUMO TOTAL, PARA CÁLCULO DO VALOR DO ESGOTO A SER | AD3: UNIDADE / DATA DA LEITURA | AE3: 46019 | AF3: 46050 | AG3: 46081 | AH3: 46109 | AV3: LEITURA | AW3: VENCTº | AX3: QUITAÇÃO | AY3: CONSUMO TOTAL (M3) | AZ3: TOTAL DA CONTA (R$) | BA3: ABASTECTº | BB3: USO DE REC. HÍDR. | BC3: PREÇO/M3 ARREDOND. | BD3: ESG. DINÂM. COLETA E TRATº | BE3: USO DE REC. HÍDR. | BF3: OBS. | BH3: FIXA | BL3: 316.4 | BN3: 233.94 | BO3: =BL3+BN3 -> 550.34 | BQ3: FIXA | BU3: 316.4 | BW3: 233.94 | BX3: =BU3+BW3 -> 550.34 | CA3: 2022 | CC3: 14.276 | CE3: 14.27 | CF3: 2.5 | CG3: =CE3*CF3 -> 35.675
A4: 45044 | B4: ÁGUA | C4: 2323.159 | D4: 0 | E4: 5724.987 | F4: 3788.481 | G4: 1673.075 | H4: 1726.402 | I4: 3879.6 | J4: 2619.173 | K4: 2149.099 | L4: 1967.14 | M4: 1873.535 | N4: 2756.556 | O4: 864.363 | P4: 5215.245 | Q4: 3149.161 | R4: =SUM(C4:Q4) -> 39709.976 | T4: CONDOM. | U4: =AY43-SUM(U5:U19) -> 18.457 | V4: =1-SUM(V5:V19) -> 0.08 | W4: =ROUND(U4,3) -> 18.457 | X4: =IF(W4>0,ROUND(AZ43-SUM(X5:X19),2),0) -> 236.41 | Y4: 0 | Z4: =ROUND(Y4,3) -> 0 | AA4: 0 | AC4: COBRADO POR | AD4: CONDOM. | AE4: 0 | AF4: 0 | AG4: 0 | AH4: 0.08 | AP4: XXX | AQ4: XXX | AR4: XXX | AS4: XXX | AT4: XXX | AV4: 45005 | AW4: 45061 | AX4: 45061 | AY4: 271 | AZ4: 3164.51 | BA4: 1815.59 | BB4: 5.04 | BC4: =ROUND((BA4+BB4)/AY4,2) -> 6.72 | BD4: 1343.37 | BE4: 0.51 | BH4: 0 A 5 | BI4: 1.42857 | BJ4: 20 | BK4: 2.34 | BL4: =ROUND(BJ4*BK4,2) -> 46.8 | BM4: 1.73 | BN4: =BJ4*BM4 -> 34.6 | BO4: =BL4+BN4 -> 81.4 | BQ4: 0 A 5 | BR4: 5 | BS4: 70 | BT4: 2.34 | BU4: =ROUND(BS4*BT4,2) -> 163.8 | BV4: 1.73 | BW4: =BS4*BV4 -> 121.1 | BX4: =BU4+BW4 -> 284.9 | CA4: 44930 | CB4: =90.43+80.67 -> 171.1 | CC4: 13.315824 | CD4: =ROUND(CB4*CC4,2) -> 2278.34 | CE4: =ROUND(CC4,2) -> 13.32 | CF4: 2.5 | CG4: =CE4*CF4 -> 33.3
A5: 45074 | B5: ÁGUA | C5: 2343.659 | D5: 0 | E5: 5772.038 | F5: 3804.161 | G5: 1681.868 | H5: 1744.873 | I5: 3895.201 | J5: 2632.161 | K5: 2161.866 | L5: 1973.59 | M5: 1881.343 | N5: 2765.982 | O5: 868.777 | P5: 5221.618 | Q5: 3160.195 | R5: =SUM(C5:Q5) -> 39907.332 | T5: 201 | U5: =C40 -> 21.886 | V5: =C41 -> 0.096 | W5: =ROUND(U5,3) -> 21.886 | X5: =ROUNDDOWN(W5*$BC$43+($BD$43+$BE$43)*V5,2) -> 281.88 | Y5: =C82 -> 0 | Z5: =ROUND(Y5,3) -> 0 | AA5: =ROUND((Z5+Z6)*$CG$9,2) -> 0 | AC5: AP (COLAR AQUI | AD5: 201 | AE5: 0.082 | AF5: 0.076 | AG5: 0.084 | AH5: 0.096 | AP5: XXX | AQ5: XXX | AR5: XXX | AS5: XXX | AT5: XXX | AV5: 45034 | AW5: 45092 | AX5: 45092 | AY5: 219 | AZ5: 2304.01 | BA5: 1320.97 | BB5: 5.17 | BC5: =ROUND((BA5+BB5)/AY5,2) -> 6.06 | BD5: 977.34 | BE5: 0.53 | BH5: 5 A 10 | BQ5: 5 A 10 | BR5: 5 | BS5: 70 | BT5: 4.987 | BU5: =ROUND(BS5*BT5,2) -> 349.09 | BV5: 3.69 | BW5: =BS5*BV5 -> 258.3 | BX5: =BU5+BW5 -> 607.39 | CA5: 45098 | CB5: 300.73 | CC5: 12.741595 | CD5: =ROUND(CB5*CC5,2) -> 3831.78 | CE5: =ROUND(CC5,2) -> 12.74 | CF5: 2.5 | CG5: =CE5*CF5 -> 31.85
A6: 45105 | B6: ÁGUA | C6: 2361.768 | D6: 0 | E6: 5827.643 | F6: 3822.973 | G6: 1695.446 | H6: 1763.177 | I6: 3911.762 | J6: 2644.027 | K6: 2174.502 | L6: 1981.599 | M6: 1899.927 | N6: 2775.917 | O6: 873.956 | P6: 5229.375 | Q6: 3177.429 | R6: =SUM(C6:Q6) -> 40139.501 | T6: 201 (ESPAÇO "201 GÁS PISC." DA TABELA DE LEITURAS, ZERADO) | U6: =D40 -> 0 | V6: =D41 -> 0 | W6: =ROUND(U6,3) -> 0 | X6: =ROUNDDOWN(W6*$BC$43+($BD$43+$BE$43)*V6,2) -> 0 | Y6: =D82 -> 0 | Z6: =ROUND(Y6,3) -> 0 | AA6: 0 | AC6: O TEXTO DA COLUNA DA TABELA 2) | AD6: 201 (ESPAÇO "201 GÁS PISC." DA TABELA DE LEITURAS, ZERADO) | AE6: 0 | AF6: 0 | AG6: 0 | AH6: 0 | AP6: XXX | AQ6: XXX | AR6: XXX | AS6: XXX | AT6: XXX | AV6: 45064 | AW6: 45124 | AX6: 45124 | AY6: 238 | AZ6: 2618.81 | BA6: 1501.7 | BB6: 5.47 | BC6: =ROUND((BA6+BB6)/AY6,2) -> 6.33 | BD6: 1111.08 | BE6: 0.56 | BH6: 10 A 15 | BQ6: 10 A 15 | BR6: 5 | BS6: 70 | BT6: 7.727 | BU6: =ROUND(BS6*BT6,2) -> 540.89 | BV6: 5.718 | BW6: =BS6*BV6 -> 400.26 | BX6: =BU6+BW6 -> 941.15 | CA6: 45296 | CB6: 280.22 | CC6: 12,809293 | CD6: =ROUND(CB6*CC6,2) -> 3589.42 | CE6: =ROUND(CC6,2) -> 12.81 | CF6: 2.5 | CG6: =CE6*CF6 -> 32.025
A7: 45138 | B7: ÁGUA | C7: 2376.043 | D7: 0 | E7: 5881.028 | F7: 3839.238 | G7: 1709.97 | H7: 1780.795 | I7: 3933.364 | J7: 2655.586 | K7: 2189.083 | L7: 1992.42 | M7: 1929.111 | N7: 2786.031 | O7: 877.042 | P7: 5236.806 | Q7: 3193.116 | R7: =SUM(C7:Q7) -> 40379.633 | T7: 202 | U7: =E40 -> 16.763 | V7: =E41 -> 0.073 | W7: =ROUND(U7,3) -> 16.763 | X7: =ROUNDDOWN(W7*$BC$43+($BD$43+$BE$43)*V7,2) -> 215.24 | Y7: =E82 -> 2.741 | Z7: =ROUND(Y7,3) -> 2.741 | AA7: =ROUND(Z7*$CG$10,2) -> 103.82 | AD7: 202 | AE7: 0.101 | AF7: 0.11 | AG7: 0.097 | AH7: 0.073 | AP7: XXX | AQ7: XXX | AR7: XXX | AS7: XXX | AT7: XXX | AV7: 45096 | AW7: 45153 | AX7: 45153 | AY7: 263 | AZ7: 3031.13 | BA7: 1739.5 | BB7: 4.11 | BC7: =ROUND((BA7+BB7)/AY7,2) -> 6.63 | BD7: 1287.06 | BE7: 0.46 | BH7: 15 A 20 | BQ7: 15 A 20 | BR7: 5 | BS7: 70 | BT7: 10.549 | BU7: =ROUND(BS7*BT7,2) -> 738.43 | BV7: 7.806 | BW7: =BS7*BV7 -> 546.42 | BX7: =BU7+BW7 -> 1284.85 | CA7: 45477 | CB7: 271.38 | CC7: 13.550888 | CD7: =ROUND(CB7*CC7,2) -> 3677.44 | CE7: =ROUND(CC7,2) -> 13.55 | CF7: 2.5 | CG7: =CE7*CF7 -> 33.875
A8: 45166 | B8: ÁGUA | C8: 2396.08 | D8: 0 | E8: 5923.725 | F8: 3855.312 | G8: 1721.456 | H8: 1799.713 | I8: 3950.691 | J8: 2666.401 | K8: 2201.556 | L8: 2001.809 | M8: 1933.433 | N8: 2795.101 | O8: 879.561 | P8: 5244.122 | Q8: 3209.97 | R8: =SUM(C8:Q8) -> 40578.93 | T8: 301 | U8: =F40 -> 19.759 | V8: =F41 -> 0.086 | W8: =ROUND(U8,3) -> 19.759 | X8: =ROUNDDOWN(W8*$BC$43+($BD$43+$BE$43)*V8,2) -> 253.65 | Y8: =F82 -> 4.059 | Z8: =ROUND(Y8,3) -> 4.059 | AA8: =ROUND(Z8*$CG$10,2) -> 153.73 | AD8: 301 | AE8: 0.086 | AF8: 0.093 | AG8: 0.086 | AH8: 0.086 | AP8: XXX | AQ8: XXX | AR8: XXX | AS8: XXX | AT8: XXX | AV8: 45126 | AW8: 45185 | AX8: 45185 | AY8: 274 | AZ8: 3213.33 | BA8: 1844.13 | BB8: 4.23 | BC8: =ROUND((BA8+BB8)/AY8,2) -> 6.75 | BD8: 1364.49 | BE8: 0.48 | BH8: 20 A 40 | BQ8: 20 A 40 | BR8: 20 | BS8: 280 | BT8: 13.418 | BU8: =ROUND(BS8*BT8,2) -> 3757.04 | BV8: 9.929 | BW8: =BS8*BV8 -> 2780.12 | BX8: =BU8+BW8 -> 6537.16 | CA8: 45645 | CB8: 300.56 | CC8: 13.889373 | CD8: =ROUND(CB8*CC8,2) -> 4174.59 | CE8: =ROUND(CC8,2) -> 13.89 | CF8: 2.5 | CG8: =CE8*CF8 -> 34.725
A9: 45197 | B9: ÁGUA | C9: 2416.782 | D9: 0 | E9: 5955.074 | F9: 3872.337 | G9: 1736.355 | H9: 1818.171 | I9: 3967.667 | J9: 2678.981 | K9: 2211.822 | L9: 2017.308 | M9: 1938.571 | N9: 2804.456 | O9: 882.839 | P9: 5251.34 | Q9: 3227.372 | R9: =SUM(C9:Q9) -> 40779.075 | T9: 302 | U9: =G40 -> 19.988 | V9: =G41 -> 0.087 | W9: =ROUND(U9,3) -> 19.988 | X9: =ROUNDDOWN(W9*$BC$43+($BD$43+$BE$43)*V9,2) -> 256.59 | Y9: =G82 -> 2.429 | Z9: =ROUND(Y9,3) -> 2.429 | AA9: =ROUND(Z9*$CG$10,2) -> 92 | AD9: 302 | AE9: 0.109 | AF9: 0.09 | AG9: 0.07 | AH9: 0.087 | AP9: XXX | AQ9: XXX | AR9: XXX | AS9: XXX | AT9: XXX | AV9: 45159 | AW9: 45215 | AX9: 45215 | AY9: 261 | AZ9: 2998.76 | BA9: 1720.47 | BB9: 4.77 | BC9: =ROUND((BA9+BB9)/AY9,2) -> 6.61 | BD9: 1272.98 | BE9: 0.54 | BH9: 40 A 60 | BQ9: 40 A 60 | BR9: 5.42857 | BS9: 76 | BT9: 16.371 | BU9: =ROUND(BS9*BT9,2) -> 1244.2 | BV9: 12.112 | BW9: =BS9*BV9 -> 920.512 | BX9: =BU9+BW9 -> 2164.712 | CA9: 45815 | CB9: 283.91 | CC9: 15.065302 | CD9: =ROUND(CB9*CC9,2) -> 4277.19 | CE9: =ROUND(CC9,2) -> 15.07 | CF9: 2.5 | CG9: =CE9*CF9 -> 37.675
A10: 45227 | B10: ÁGUA | C10: 2436.831 | D10: 0 | E10: 5972.821 | F10: 3892.028 | G10: 1750.664 | H10: 1835.107 | I10: 3987.57 | J10: 2690.956 | K10: 2223.174 | L10: 2028.352 | M10: 1943.757 | N10: 2814.368 | O10: 885.629 | P10: 5260.244 | Q10: 3243.387 | R10: =SUM(C10:Q10) -> 40964.888 | T10: 401 | U10: =H40 -> 25.559 | V10: =H41 -> 0.112 | W10: =ROUND(U10,3) -> 25.559 | X10: =ROUNDDOWN(W10*$BC$43+($BD$43+$BE$43)*V10,2) -> 329.05 | Y10: =H82 -> 1.414 | Z10: =ROUND(Y10,3) -> 1.414 | AA10: =ROUND(Z10*$CG$10,2) -> 53.56 | AD10: 401 | AE10: 0.127 | AF10: 0.141 | AG10: 0.136 | AH10: 0.112 | AP10: XXX | AQ10: XXX | AR10: XXX | AS10: XXX | AT10: XXX | AV10: 45189 | AW10: 45245 | AX10: 45245 | AY10: 242 | AZ10: =BA10+BB10+BD10+BE10 -> 2684.4 | BA10: 1539.74 | BB10: 4.87 | BC10: =ROUND((BA10+BB10)/AY10,2) -> 6.38 | BD10: 1139.24 | BE10: 0.55 | BH10: SOMA | BI10: =SUM(BI4:BI8) -> 1.42857 | BJ10: =SUM(BJ4:BJ8) -> 20 | BL10: =SUM(BL3:BL8) -> 363.2 | BN10: =SUM(BN3:BN8) -> 268.54 | BO10: =SUM(BO3:BO8) -> 631.74 | BQ10: SOMA | BR10: =SUM(BR4:BR9) -> 45.42857 | BS10: =SUM(BS4:BS9) -> 636 | BU10: =SUM(BU3:BU9) -> 7109.85 | BW10: =SUM(BW3:BW9) -> 5260.652 | BX10: =SUM(BX3:BX9) -> 12370.502 | CA10: 46025 | CB10: 320 | CC10: 15.145313 | CD10: =ROUND(CB10*CC10,2) -> 4846.5 | CE10: =ROUND(CC10,2) -> 15.15 | CF10: 2.5 | CG10: =CE10*CF10 -> 37.875
A11: 45258 | B11: ÁGUA | C11: 2455.727 | D11: 0 | E11: 6004.368 | F11: 3909.588 | G11: 1769.361 | H11: 1854.208 | I11: 4010.335 | J11: 2703.906 | K11: 2237.708 | L11: 2043.882 | M11: 1952.156 | N11: 2825.211 | O11: 888.719 | P11: 5262.031 | Q11: 3262.162 | R11: =SUM(C11:Q11) -> 41179.362 | T11: 402 | U11: =I40 -> 23.777 | V11: =I41 -> 0.104 | W11: =ROUND(U11,3) -> 23.777 | X11: =ROUNDDOWN(W11*$BC$43+($BD$43+$BE$43)*V11,2) -> 305.87 | Y11: =I82 -> 4.82 | Z11: =ROUND(Y11,3) -> 4.82 | AA11: =ROUND(Z11*$CG$10,2) -> 182.56 | AD11: 402 | AE11: 0.073 | AF11: 0.086 | AG11: 0.094 | AH11: 0.104 | AP11: XXX | AQ11: XXX | AR11: XXX | AS11: XXX | AT11: XXX | AV11: 45222 | AW11: 45275 | AX11: 45275 | AY11: 239 | AZ11: =BA11+BB11+BD11+BE11 -> 2634.49 | BA11: 1511.21 | BB11: 4.64 | BC11: =ROUND((BA11+BB11)/AY11,2) -> 6.34 | BD11: 1118.12 | BE11: 0.52 | BH11: USO REC. HÍDR. ÁGUA | BO11: 15.61 | BQ11: USO REC. HÍDR. ÁGUA | BX11: 15.28
A12: 45288 | B12: ÁGUA | C12: 2474.42 | D12: 0 | E12: 6053.424 | F12: 3931.077 | G12: 1784.135 | H12: 1871.797 | I12: 4032.631 | J12: 2715.053 | K12: 2250.844 | L12: 2059.568 | M12: 1968.013 | N12: 2836.379 | O12: 891.618 | P12: 5265.855 | Q12: 3281.035 | R12: =SUM(C12:Q12) -> 41415.849 | T12: 501 | U12: =J40 -> 25.421 | V12: =J41 -> 0.111 | W12: =ROUND(U12,3) -> 25.421 | X12: =ROUNDDOWN(W12*$BC$43+($BD$43+$BE$43)*V12,2) -> 326.78 | Y12: =J82 -> 1.213 | Z12: =ROUND(Y12,3) -> 1.213 | AA12: =ROUND(Z12*$CG$10,2) -> 45.94 | AD12: 501 | AE12: 0.06 | AF12: 0.128 | AG12: 0.185 | AH12: 0.111 | AP12: XXX | AQ12: XXX | AR12: XXX | AS12: XXX | AT12: XXX | AV12: 45253 | AW12: 45306 | AX12: 45306 | AY12: 246 | AZ12: =BA12+BB12+BD12+BE12 -> 2749.91 | BA12: 1577.79 | BB12: 4.25 | BC12: =ROUND((BA12+BB12)/AY12,2) -> 6.43 | BD12: 1167.39 | BE12: 0.48 | BH12: USO REC. HÍDR. ESGOTO | BO12: 3.43 | BQ12: USO REC. HÍDR. ESGOTO | BX12: 3.36
A13: 45319 | B13: ÁGUA | C13: 2491.821 | D13: 0 | E13: 6102.368 | F13: 3953.12 | G13: 1800.569 | H13: 1885.724 | I13: 4058.137 | J13: 2726.861 | K13: 2265.914 | L13: 2075.591 | M13: 1994.272 | N13: 2850.035 | O13: 894.558 | P13: 5267.996 | Q13: 3300.08 | R13: =SUM(C13:Q13) -> 41667.046 | T13: 502 | U13: =K40 -> 13.441 | V13: =K41 -> 0.059 | W13: =ROUND(U13,3) -> 13.441 | X13: =ROUNDDOWN(W13*$BC$43+($BD$43+$BE$43)*V13,2) -> 173.17 | Y13: =K82 -> 1.029 | Z13: =ROUND(Y13,3) -> 1.029 | AA13: =ROUND(Z13*$CG$10,2) -> 38.97 | AD13: 502 | AE13: 0.056 | AF13: 0.069 | AG13: 0.057 | AH13: 0.059 | AP13: XXX | AQ13: XXX | AR13: XXX | AS13: XXX | AT13: XXX | AV13: 45281 | AW13: 45337 | AX13: 45337 | AY13: 243 | AZ13: =BA13+BB13+BD13+BE13 -> 2699.88 | BA13: 1549.26 | BB13: 3.9 | BC13: =ROUND((BA13+BB13)/AY13,2) -> 6.39 | BD13: 1146.28 | BE13: 0.44 | BH13: TOTAL | BO13: =BO10+BO11+BO12 -> 650.78 | BQ13: TOTAL | BX13: =BX10+BX11+BX12 -> 12389.142 | CA13: GÁS: HÁ 2 TANQUES DE 200 KG CADA. 1KG COMPRADO É IGUAL A 2,5M3 CONSUMIDOS. ESSE VALOR É CORRIGIDO A CADA ABASTECIMENTO. 2ª VARIÁVEL DA FÓRMULA (COLUNA "CONSUMO M3"): VALOR É IGUAL A 2,5 X O PREÇO UNITÁRIO DO QUILO, QUE SERÁ VERIFICADO NO ÚLTIMO ABASTECIMENTO FEITO
A14: 45350 | B14: ÁGUA | C14: 2505.809 | D14: 0 | E14: 6151.25 | F14: 3971.944 | G14: 1815.415 | H14: 1905.788 | I14: 4084.603 | J14: 2737.65 | K14: 2281.466 | L14: 2090.551 | M14: 2001.276 | N14: 2861.248 | O14: 898.348 | P14: 5268.242 | Q14: 3317.755 | R14: =SUM(C14:Q14) -> 41891.345 | T14: 601 | U14: =L40 -> 3.979 | V14: =L41 -> 0.017 | W14: =ROUND(U14,3) -> 3.979 | X14: =ROUNDDOWN(W14*$BC$43+($BD$43+$BE$43)*V14,2) -> 50.68 | Y14: =L82 -> 0.582 | Z14: =ROUND(Y14,3) -> 0.582 | AA14: =ROUND(Z14*$CG$10,2) -> 22.04 | AD14: 601 | AE14: 0.022 | AF14: 0.025 | AG14: 0.014 | AH14: 0.017 | AP14: XXX | AQ14: XXX | AR14: XXX | AS14: XXX | AT14: XXX | AV14: 45313 | AW14: 45366 | AX14: 45366 | AY14: 293 | AZ14: =BA14+BB14+BD14+BE14 -> 3689.84 | BA14: 2117.99 | BB14: 4.15 | BC14: =ROUND((BA14+BB14)/AY14,2) -> 7.24 | BD14: 1567.23 | BE14: 0.47 | BH14: LEITURA ERRADA QUE FOI FEITA EM 22/07/25: | BN14: 5021 | BO14: M3 | BQ14: LEITURA ATUAL, VERIFIQUEI QUE ESTÁ CORRETA: | BW14: 5657 | BX14: M3 | CA14: GÁS DO 201: TEM UM MEDIDOR A PARTE. NO APTº A MEDIÇÃO GERALMENTE É ZERO, PORQUE TEM FOGÃO ELÉTRICO
